Connected to PostgreSQL database. Version: PostgreSQL 16.6 on x86_64-pc-linux-gnu, compiled by gcc (Debian 10.2.1-6) 10.2.1 20210110, 64-bit
Database connection closed.
Connected to PostgreSQL database. Version: PostgreSQL 16.6 on x86_64-pc-linux-gnu, compiled by gcc (Debian 10.2.1-6) 10.2.1 20210110, 64-bit
Database connection closed.
Watching for file changes with StatReloader
Performing system checks...

Exception in thread django-main-thread:
Traceback (most recent call last):
  File "/nix/store/clx0mcir7qw8zk36zbr4jra789g3knf6-python3-3.11.10/lib/python3.11/threading.py", line 1045, in _bootstrap_inner
    self.run()
  File "/nix/store/clx0mcir7qw8zk36zbr4jra789g3knf6-python3-3.11.10/lib/python3.11/threading.py", line 982, in run
    self._target(*self._args, **self._kwargs)
  File "/nix/store/6dhxaza18jl6d29yczsqp0nf7lr07avj-python3.11-django-4.2.12/lib/python3.11/site-packages/django/utils/autoreload.py", line 64, in wrapper
    fn(*args, **kwargs)
  File "/nix/store/6dhxaza18jl6d29yczsqp0nf7lr07avj-python3.11-django-4.2.12/lib/python3.11/site-packages/django/core/management/commands/runserver.py", line 133, in inner_run
    self.check(display_num_errors=True)
  File "/nix/store/6dhxaza18jl6d29yczsqp0nf7lr07avj-python3.11-django-4.2.12/lib/python3.11/site-packages/django/core/management/base.py", line 485, in check
    all_issues = checks.run_checks(
                 ^^^^^^^^^^^^^^^^^^
  File "/nix/store/6dhxaza18jl6d29yczsqp0nf7lr07avj-python3.11-django-4.2.12/lib/python3.11/site-packages/django/core/checks/registry.py", line 88, in run_checks
    new_errors = check(app_configs=app_configs, databases=databases)
                 ^^^^^^^^^^^^^^^^^^^^^^^^^^^^^^^^^^^^^^^^^^^^^^^^^^^
  File "/nix/store/6dhxaza18jl6d29yczsqp0nf7lr07avj-python3.11-django-4.2.12/lib/python3.11/site-packages/django/core/checks/urls.py", line 42, in check_url_namespaces_unique
    all_namespaces = _load_all_namespaces(resolver)
                     ^^^^^^^^^^^^^^^^^^^^^^^^^^^^^^
  File "/nix/store/6dhxaza18jl6d29yczsqp0nf7lr07avj-python3.11-django-4.2.12/lib/python3.11/site-packages/django/core/checks/urls.py", line 61, in _load_all_namespaces
    url_patterns = getattr(resolver, "url_patterns", [])
                   ^^^^^^^^^^^^^^^^^^^^^^^^^^^^^^^^^^^^^
  File "/nix/store/6dhxaza18jl6d29yczsqp0nf7lr07avj-python3.11-django-4.2.12/lib/python3.11/site-packages/django/utils/functional.py", line 57, in __get__
    res = instance.__dict__[self.name] = self.func(instance)
                                         ^^^^^^^^^^^^^^^^^^^
  File "/nix/store/6dhxaza18jl6d29yczsqp0nf7lr07avj-python3.11-django-4.2.12/lib/python3.11/site-packages/django/urls/resolvers.py", line 715, in url_patterns
    patterns = getattr(self.urlconf_module, "urlpatterns", self.urlconf_module)
                       ^^^^^^^^^^^^^^^^^^^
  File "/nix/store/6dhxaza18jl6d29yczsqp0nf7lr07avj-python3.11-django-4.2.12/lib/python3.11/site-packages/django/utils/functional.py", line 57, in __get__
    res = instance.__dict__[self.name] = self.func(instance)
                                         ^^^^^^^^^^^^^^^^^^^
  File "/nix/store/6dhxaza18jl6d29yczsqp0nf7lr07avj-python3.11-django-4.2.12/lib/python3.11/site-packages/django/urls/resolvers.py", line 708, in urlconf_module
    return import_module(self.urlconf_name)
           ^^^^^^^^^^^^^^^^^^^^^^^^^^^^^^^^
  File "/nix/store/clx0mcir7qw8zk36zbr4jra789g3knf6-python3-3.11.10/lib/python3.11/importlib/__init__.py", line 126, in import_module
    return _bootstrap._gcd_import(name[level:], package, level)
           ^^^^^^^^^^^^^^^^^^^^^^^^^^^^^^^^^^^^^^^^^^^^^^^^^^^^
  File "<frozen importlib._bootstrap>", line 1204, in _gcd_import
  File "<frozen importlib._bootstrap>", line 1176, in _find_and_load
  File "<frozen importlib._bootstrap>", line 1147, in _find_and_load_unlocked
  File "<frozen importlib._bootstrap>", line 690, in _load_unlocked
  File "<frozen importlib._bootstrap_external>", line 940, in exec_module
  File "<frozen importlib._bootstrap>", line 241, in _call_with_frames_removed
  File "/home/runner/workspace/myproject/urls.py", line 27, in <module>
    path('', include('gametube.urls')),
             ^^^^^^^^^^^^^^^^^^^^^^^^
  File "/nix/store/6dhxaza18jl6d29yczsqp0nf7lr07avj-python3.11-django-4.2.12/lib/python3.11/site-packages/django/urls/conf.py", line 38, in include
    urlconf_module = import_module(urlconf_module)
                     ^^^^^^^^^^^^^^^^^^^^^^^^^^^^^
  File "/nix/store/clx0mcir7qw8zk36zbr4jra789g3knf6-python3-3.11.10/lib/python3.11/importlib/__init__.py", line 126, in import_module
    return _bootstrap._gcd_import(name[level:], package, level)
           ^^^^^^^^^^^^^^^^^^^^^^^^^^^^^^^^^^^^^^^^^^^^^^^^^^^^
  File "<frozen importlib._bootstrap>", line 1204, in _gcd_import
  File "<frozen importlib._bootstrap>", line 1176, in _find_and_load
  File "<frozen importlib._bootstrap>", line 1147, in _find_and_load_unlocked
  File "<frozen importlib._bootstrap>", line 690, in _load_unlocked
  File "<frozen importlib._bootstrap_external>", line 940, in exec_module
  File "<frozen importlib._bootstrap>", line 241, in _call_with_frames_removed
  File "/home/runner/workspace/gametube/urls.py", line 2, in <module>
    from . import views
  File "/home/runner/workspace/gametube/views.py", line 159
    category = request.POST.get('category')
    ^^^^^^^^
SyntaxError: expected 'except' or 'finally' block