Connected to PostgreSQL database. Version: PostgreSQL 16.6 on x86_64-pc-linux-gnu, compiled by gcc (Debian 10.2.1-6) 10.2.1 20210110, 64-bit
Database connection closed.
Performing system checks...

Traceback (most recent call last):
  File "/home/runner/workspace/main.py", line 9, in <module>
    execute_from_command_line(["", "runserver", f"0.0.0.0:{port}", "--noreload"])
  File "/nix/store/6dhxaza18jl6d29yczsqp0nf7lr07avj-python3.11-django-4.2.12/lib/python3.11/site-packages/django/core/management/__init__.py", line 442, in execute_from_command_line
    utility.execute()
  File "/nix/store/6dhxaza18jl6d29yczsqp0nf7lr07avj-python3.11-django-4.2.12/lib/python3.11/site-packages/django/core/management/__init__.py", line 436, in execute
    self.fetch_command(subcommand).run_from_argv(self.argv)
  File "/nix/store/6dhxaza18jl6d29yczsqp0nf7lr07avj-python3.11-django-4.2.12/lib/python3.11/site-packages/django/core/management/base.py", line 412, in run_from_argv
    self.execute(*args, **cmd_options)
  File "/nix/store/6dhxaza18jl6d29yczsqp0nf7lr07avj-python3.11-django-4.2.12/lib/python3.11/site-packages/django/core/management/commands/runserver.py", line 74, in execute
    super().execute(*args, **options)
  File "/nix/store/6dhxaza18jl6d29yczsqp0nf7lr07avj-python3.11-django-4.2.12/lib/python3.11/site-packages/django/core/management/base.py", line 458, in execute
    output = self.handle(*args, **options)
             ^^^^^^^^^^^^^^^^^^^^^^^^^^^^^
  File "/nix/store/6dhxaza18jl6d29yczsqp0nf7lr07avj-python3.11-django-4.2.12/lib/python3.11/site-packages/django/core/management/commands/runserver.py", line 111, in handle
    self.run(**options)
  File "/nix/store/6dhxaza18jl6d29yczsqp0nf7lr07avj-python3.11-django-4.2.12/lib/python3.11/site-packages/django/core/management/commands/runserver.py", line 120, in run
    self.inner_run(None, **options)
  File "/nix/store/6dhxaza18jl6d29yczsqp0nf7lr07avj-python3.11-django-4.2.12/lib/python3.11/site-packages/django/core/management/commands/runserver.py", line 133, in inner_run
    self.check(display_num_errors=True)
  File "/nix/store/6dhxaza18jl6d29yczsqp0nf7lr07avj-python3.11-django-4.2.12/lib/python3.11/site-packages/django/core/management/base.py", line 485, in check
    all_issues = checks.run_checks(
                 ^^^^^^^^^^^^^^^^^^
  File "/nix/store/6dhxaza18jl6d29yczsqp0nf7lr07avj-python3.11-django-4.2.12/lib/python3.11/site-packages/django/core/checks/registry.py", line 88, in run_checks
    new_errors = check(app_configs=app_configs, databases=databases)
                 ^^^^^^^^^^^^^^^^^^^^^^^^^^^^^^^^^^^^^^^^^^^^^^^^^^^
  File "/nix/store/6dhxaza18jl6d29yczsqp0nf7lr07avj-python3.11-django-4.2.12/lib/python3.11/site-packages/django/core/checks/urls.py", line 14, in check_url_config
    return check_resolver(resolver)
           ^^^^^^^^^^^^^^^^^^^^^^^^
  File "/nix/store/6dhxaza18jl6d29yczsqp0nf7lr07avj-python3.11-django-4.2.12/lib/python3.11/site-packages/django/core/checks/urls.py", line 24, in check_resolver
    return check_method()
           ^^^^^^^^^^^^^^
  File "/nix/store/6dhxaza18jl6d29yczsqp0nf7lr07avj-python3.11-django-4.2.12/lib/python3.11/site-packages/django/urls/resolvers.py", line 494, in check
    for pattern in self.url_patterns:
                   ^^^^^^^^^^^^^^^^^
  File "/nix/store/6dhxaza18jl6d29yczsqp0nf7lr07avj-python3.11-django-4.2.12/lib/python3.11/site-packages/django/utils/functional.py", line 57, in __get__
    res = instance.__dict__[self.name] = self.func(instance)
                                         ^^^^^^^^^^^^^^^^^^^
  File "/nix/store/6dhxaza18jl6d29yczsqp0nf7lr07avj-python3.11-django-4.2.12/lib/python3.11/site-packages/django/urls/resolvers.py", line 715, in url_patterns
    patterns = getattr(self.urlconf_module, "urlpatterns", self.urlconf_module)
                       ^^^^^^^^^^^^^^^^^^^
  File "/nix/store/6dhxaza18jl6d29yczsqp0nf7lr07avj-python3.11-django-4.2.12/lib/python3.11/site-packages/django/utils/functional.py", line 57, in __get__
    res = instance.__dict__[self.name] = self.func(instance)
                                         ^^^^^^^^^^^^^^^^^^^
  File "/nix/store/6dhxaza18jl6d29yczsqp0nf7lr07avj-python3.11-django-4.2.12/lib/python3.11/site-packages/django/urls/resolvers.py", line 708, in urlconf_module
    return import_module(self.urlconf_name)
           ^^^^^^^^^^^^^^^^^^^^^^^^^^^^^^^^
  File "/nix/store/clx0mcir7qw8zk36zbr4jra789g3knf6-python3-3.11.10/lib/python3.11/importlib/__init__.py", line 126, in import_module
    return _bootstrap._gcd_import(name[level:], package, level)
           ^^^^^^^^^^^^^^^^^^^^^^^^^^^^^^^^^^^^^^^^^^^^^^^^^^^^
  File "<frozen importlib._bootstrap>", line 1204, in _gcd_import
  File "<frozen importlib._bootstrap>", line 1176, in _find_and_load
  File "<frozen importlib._bootstrap>", line 1147, in _find_and_load_unlocked
  File "<frozen importlib._bootstrap>", line 690, in _load_unlocked
  File "<frozen importlib._bootstrap_external>", line 940, in exec_module
  File "<frozen importlib._bootstrap>", line 241, in _call_with_frames_removed
  File "/home/runner/workspace/myproject/urls.py", line 27, in <module>
    path('', include('gametube.urls')),
             ^^^^^^^^^^^^^^^^^^^^^^^^
  File "/nix/store/6dhxaza18jl6d29yczsqp0nf7lr07avj-python3.11-django-4.2.12/lib/python3.11/site-packages/django/urls/conf.py", line 38, in include
    urlconf_module = import_module(urlconf_module)
                     ^^^^^^^^^^^^^^^^^^^^^^^^^^^^^
  File "/nix/store/clx0mcir7qw8zk36zbr4jra789g3knf6-python3-3.11.10/lib/python3.11/importlib/__init__.py", line 126, in import_module
    return _bootstrap._gcd_import(name[level:], package, level)
           ^^^^^^^^^^^^^^^^^^^^^^^^^^^^^^^^^^^^^^^^^^^^^^^^^^^^
  File "<frozen importlib._bootstrap>", line 1204, in _gcd_import
  File "<frozen importlib._bootstrap>", line 1176, in _find_and_load
  File "<frozen importlib._bootstrap>", line 1147, in _find_and_load_unlocked
  File "<frozen importlib._bootstrap>", line 690, in _load_unlocked
  File "<frozen importlib._bootstrap_external>", line 940, in exec_module
  File "<frozen importlib._bootstrap>", line 241, in _call_with_frames_removed
  File "/home/runner/workspace/gametube/urls.py", line 10, in <module>
    path('upload/', views.upload_video, name='upload_video'),
                    ^^^^^^^^^^^^^^^^^^
AttributeError: module 'gametube.views' has no attribute 'upload_video'