Error connecting to PostgreSQL: connection to server on socket "/run/postgresql/.s.PGSQL.5432" failed: No such file or directory
    Is the server running locally and accepting connections on that socket?

Performing system checks...

System check identified no issues (0 silenced).

You have 12 unapplied migration(s). Your project may not work properly until you apply the migrations for app(s): gametube.
Run 'python manage.py migrate' to apply them.
February 11, 2025 - 13:47:20
Django version 4.2.12, using settings 'myproject.settings'
Starting development server at http://0.0.0.0:8080/
Quit the server with CONTROL-C.

Traceback (most recent call last):
  File "/nix/store/6dhxaza18jl6d29yczsqp0nf7lr07avj-python3.11-django-4.2.12/lib/python3.11/site-packages/django/contrib/sessions/backends/base.py", line 187, in _get_session
    return self._session_cache
           ^^^^^^^^^^^^^^^^^^^
AttributeError: 'SessionStore' object has no attribute '_session_cache'

During handling of the above exception, another exception occurred:

Traceback (most recent call last):
  File "/nix/store/6dhxaza18jl6d29yczsqp0nf7lr07avj-python3.11-django-4.2.12/lib/python3.11/site-packages/django/db/backends/utils.py", line 89, in _execute
    return self.cursor.execute(sql, params)
           ^^^^^^^^^^^^^^^^^^^^^^^^^^^^^^^^
psycopg2.errors.UndefinedTable: relation "django_session" does not exist
LINE 1: ...ession_data", "django_session"."expire_date" FROM "django_se...
                                                             ^


The above exception was the direct cause of the following exception:

Traceback (most recent call last):
  File "/nix/store/6dhxaza18jl6d29yczsqp0nf7lr07avj-python3.11-django-4.2.12/lib/python3.11/site-packages/django/core/handlers/exception.py", line 55, in inner
    response = get_response(request)
               ^^^^^^^^^^^^^^^^^^^^^
  File "/nix/store/6dhxaza18jl6d29yczsqp0nf7lr07avj-python3.11-django-4.2.12/lib/python3.11/site-packages/django/utils/deprecation.py", line 133, in __call__
    response = self.process_request(request)
               ^^^^^^^^^^^^^^^^^^^^^^^^^^^^^
  File "/nix/store/6dhxaza18jl6d29yczsqp0nf7lr07avj-python3.11-django-4.2.12/lib/python3.11/site-packages/django/middleware/csrf.py", line 408, in process_request
    csrf_secret = self._get_secret(request)
                  ^^^^^^^^^^^^^^^^^^^^^^^^^
  File "/nix/store/6dhxaza18jl6d29yczsqp0nf7lr07avj-python3.11-django-4.2.12/lib/python3.11/site-packages/django/middleware/csrf.py", line 236, in _get_secret
    csrf_secret = request.session.get(CSRF_SESSION_KEY)
                  ^^^^^^^^^^^^^^^^^^^^^^^^^^^^^^^^^^^^^
  File "/nix/store/6dhxaza18jl6d29yczsqp0nf7lr07avj-python3.11-django-4.2.12/lib/python3.11/site-packages/django/contrib/sessions/backends/base.py", line 68, in get
    return self._session.get(key, default)
           ^^^^^^^^^^^^^
  File "/nix/store/6dhxaza18jl6d29yczsqp0nf7lr07avj-python3.11-django-4.2.12/lib/python3.11/site-packages/django/contrib/sessions/backends/base.py", line 192, in _get_session
    self._session_cache = self.load()
                          ^^^^^^^^^^^
  File "/nix/store/6dhxaza18jl6d29yczsqp0nf7lr07avj-python3.11-django-4.2.12/lib/python3.11/site-packages/django/contrib/sessions/backends/db.py", line 42, in load
    s = self._get_session_from_db()
        ^^^^^^^^^^^^^^^^^^^^^^^^^^^
  File "/nix/store/6dhxaza18jl6d29yczsqp0nf7lr07avj-python3.11-django-4.2.12/lib/python3.11/site-packages/django/contrib/sessions/backends/db.py", line 32, in _get_session_from_db
    return self.model.objects.get(
           ^^^^^^^^^^^^^^^^^^^^^^^
  File "/nix/store/6dhxaza18jl6d29yczsqp0nf7lr07avj-python3.11-django-4.2.12/lib/python3.11/site-packages/django/db/models/manager.py", line 87, in manager_method
    return getattr(self.get_queryset(), name)(*args, **kwargs)
           ^^^^^^^^^^^^^^^^^^^^^^^^^^^^^^^^^^^^^^^^^^^^^^^^^^^
  File "/nix/store/6dhxaza18jl6d29yczsqp0nf7lr07avj-python3.11-django-4.2.12/lib/python3.11/site-packages/django/db/models/query.py", line 633, in get
    num = len(clone)
          ^^^^^^^^^^
  File "/nix/store/6dhxaza18jl6d29yczsqp0nf7lr07avj-python3.11-django-4.2.12/lib/python3.11/site-packages/django/db/models/query.py", line 380, in __len__
    self._fetch_all()
  File "/nix/store/6dhxaza18jl6d29yczsqp0nf7lr07avj-python3.11-django-4.2.12/lib/python3.11/site-packages/django/db/models/query.py", line 1881, in _fetch_all
    self._result_cache = list(self._iterable_class(self))
                         ^^^^^^^^^^^^^^^^^^^^^^^^^^^^^^^^
  File "/nix/store/6dhxaza18jl6d29yczsqp0nf7lr07avj-python3.11-django-4.2.12/lib/python3.11/site-packages/django/db/models/query.py", line 91, in __iter__
    results = compiler.execute_sql(
              ^^^^^^^^^^^^^^^^^^^^^
  File "/nix/store/6dhxaza18jl6d29yczsqp0nf7lr07avj-python3.11-django-4.2.12/lib/python3.11/site-packages/django/db/models/sql/compiler.py", line 1562, in execute_sql
    cursor.execute(sql, params)
  File "/nix/store/6dhxaza18jl6d29yczsqp0nf7lr07avj-python3.11-django-4.2.12/lib/python3.11/site-packages/django/db/backends/utils.py", line 67, in execute
    return self._execute_with_wrappers(
           ^^^^^^^^^^^^^^^^^^^^^^^^^^^^
  File "/nix/store/6dhxaza18jl6d29yczsqp0nf7lr07avj-python3.11-django-4.2.12/lib/python3.11/site-packages/django/db/backends/utils.py", line 80, in _execute_with_wrappers
    return executor(sql, params, many, context)
           ^^^^^^^^^^^^^^^^^^^^^^^^^^^^^^^^^^^^
  File "/nix/store/6dhxaza18jl6d29yczsqp0nf7lr07avj-python3.11-django-4.2.12/lib/python3.11/site-packages/django/db/backends/utils.py", line 84, in _execute
    with self.db.wrap_database_errors:
  File "/nix/store/6dhxaza18jl6d29yczsqp0nf7lr07avj-python3.11-django-4.2.12/lib/python3.11/site-packages/django/db/utils.py", line 91, in __exit__
    raise dj_exc_value.with_traceback(traceback) from exc_value
  File "/nix/store/6dhxaza18jl6d29yczsqp0nf7lr07avj-python3.11-django-4.2.12/lib/python3.11/site-packages/django/db/backends/utils.py", line 89, in _execute
    return self.cursor.execute(sql, params)
           ^^^^^^^^^^^^^^^^^^^^^^^^^^^^^^^^
django.db.utils.ProgrammingError: relation "django_session" does not exist
LINE 1: ...ession_data", "django_session"."expire_date" FROM "django_se...
                                                             ^


During handling of the above exception, another exception occurred:

Traceback (most recent call last):
  File "/nix/store/6dhxaza18jl6d29yczsqp0nf7lr07avj-python3.11-django-4.2.12/lib/python3.11/site-packages/django/contrib/sessions/backends/base.py", line 187, in _get_session
    return self._session_cache
           ^^^^^^^^^^^^^^^^^^^
AttributeError: 'SessionStore' object has no attribute '_session_cache'

During handling of the above exception, another exception occurred:

Traceback (most recent call last):
  File "/nix/store/6dhxaza18jl6d29yczsqp0nf7lr07avj-python3.11-django-4.2.12/lib/python3.11/site-packages/django/db/backends/utils.py", line 89, in _execute
    return self.cursor.execute(sql, params)
           ^^^^^^^^^^^^^^^^^^^^^^^^^^^^^^^^
psycopg2.errors.UndefinedTable: relation "django_session" does not exist
LINE 1: ...ession_data", "django_session"."expire_date" FROM "django_se...
                                                             ^


The above exception was the direct cause of the following exception:

Traceback (most recent call last):
  File "/nix/store/6dhxaza18jl6d29yczsqp0nf7lr07avj-python3.11-django-4.2.12/lib/python3.11/site-packages/django/core/handlers/exception.py", line 55, in inner
    response = get_response(request)
               ^^^^^^^^^^^^^^^^^^^^^
  File "/nix/store/6dhxaza18jl6d29yczsqp0nf7lr07avj-python3.11-django-4.2.12/lib/python3.11/site-packages/django/utils/deprecation.py", line 134, in __call__
    response = response or self.get_response(request)
                           ^^^^^^^^^^^^^^^^^^^^^^^^^^
  File "/nix/store/6dhxaza18jl6d29yczsqp0nf7lr07avj-python3.11-django-4.2.12/lib/python3.11/site-packages/django/core/handlers/exception.py", line 57, in inner
    response = response_for_exception(request, exc)
               ^^^^^^^^^^^^^^^^^^^^^^^^^^^^^^^^^^^^
  File "/nix/store/6dhxaza18jl6d29yczsqp0nf7lr07avj-python3.11-django-4.2.12/lib/python3.11/site-packages/django/core/handlers/exception.py", line 140, in response_for_exception
    response = handle_uncaught_exception(
               ^^^^^^^^^^^^^^^^^^^^^^^^^^
  File "/nix/store/6dhxaza18jl6d29yczsqp0nf7lr07avj-python3.11-django-4.2.12/lib/python3.11/site-packages/django/core/handlers/exception.py", line 185, in handle_uncaught_exception
    return callback(request)
           ^^^^^^^^^^^^^^^^^
  File "/nix/store/6dhxaza18jl6d29yczsqp0nf7lr07avj-python3.11-django-4.2.12/lib/python3.11/site-packages/django/utils/decorators.py", line 126, in _wrapper_view
    result = middleware.process_request(request)
             ^^^^^^^^^^^^^^^^^^^^^^^^^^^^^^^^^^^
Traceback (most recent call last):
  File "/nix/store/6dhxaza18jl6d29yczsqp0nf7lr07avj-python3.11-django-4.2.12/lib/python3.11/site-packages/django/middleware/csrf.py", line 408, in process_request
    csrf_secret = self._get_secret(request)
                  ^^^^^^^^^^^^^^^^^^^^^^^^^
  File "/nix/store/6dhxaza18jl6d29yczsqp0nf7lr07avj-python3.11-django-4.2.12/lib/python3.11/site-packages/django/contrib/sessions/backends/base.py", line 187, in _get_session
    return self._session_cache
           ^^^^^^^^^^^^^^^^^^^
  File "/nix/store/6dhxaza18jl6d29yczsqp0nf7lr07avj-python3.11-django-4.2.12/lib/python3.11/site-packages/django/middleware/csrf.py", line 236, in _get_secret
    csrf_secret = request.session.get(CSRF_SESSION_KEY)
                  ^^^^^^^^^^^^^^^^^^^^^^^^^^^^^^^^^^^^^
  File "/nix/store/6dhxaza18jl6d29yczsqp0nf7lr07avj-python3.11-django-4.2.12/lib/python3.11/site-packages/django/contrib/sessions/backends/base.py", line 68, in get
    return self._session.get(key, default)
           ^^^^^^^^^^^^^
  File "/nix/store/6dhxaza18jl6d29yczsqp0nf7lr07avj-python3.11-django-4.2.12/lib/python3.11/site-packages/django/contrib/sessions/backends/base.py", line 192, in _get_session
    self._session_cache = self.load()
                          ^^^^^^^^^^^
  File "/nix/store/6dhxaza18jl6d29yczsqp0nf7lr07avj-python3.11-django-4.2.12/lib/python3.11/site-packages/django/contrib/sessions/backends/db.py", line 42, in load
    s = self._get_session_from_db()
        ^^^^^^^^^^^^^^^^^^^^^^^^^^^
  File "/nix/store/6dhxaza18jl6d29yczsqp0nf7lr07avj-python3.11-django-4.2.12/lib/python3.11/site-packages/django/contrib/sessions/backends/db.py", line 32, in _get_session_from_db
    return self.model.objects.get(
           ^^^^^^^^^^^^^^^^^^^^^^^
  File "/nix/store/6dhxaza18jl6d29yczsqp0nf7lr07avj-python3.11-django-4.2.12/lib/python3.11/site-packages/django/db/models/manager.py", line 87, in manager_method
    return getattr(self.get_queryset(), name)(*args, **kwargs)
           ^^^^^^^^^^^^^^^^^^^^^^^^^^^^^^^^^^^^^^^^^^^^^^^^^^^
  File "/nix/store/6dhxaza18jl6d29yczsqp0nf7lr07avj-python3.11-django-4.2.12/lib/python3.11/site-packages/django/db/models/query.py", line 633, in get
    num = len(clone)
          ^^^^^^^^^^
  File "/nix/store/6dhxaza18jl6d29yczsqp0nf7lr07avj-python3.11-django-4.2.12/lib/python3.11/site-packages/django/db/models/query.py", line 380, in __len__
    self._fetch_all()
  File "/nix/store/6dhxaza18jl6d29yczsqp0nf7lr07avj-python3.11-django-4.2.12/lib/python3.11/site-packages/django/db/models/query.py", line 1881, in _fetch_all
    self._result_cache = list(self._iterable_class(self))
                         ^^^^^^^^^^^^^^^^^^^^^^^^^^^^^^^^
AttributeError: 'SessionStore' object has no attribute '_session_cache'
  File "/nix/store/6dhxaza18jl6d29yczsqp0nf7lr07avj-python3.11-django-4.2.12/lib/python3.11/site-packages/django/db/models/query.py", line 91, in __iter__
    results = compiler.execute_sql(
              ^^^^^^^^^^^^^^^^^^^^^
  File "/nix/store/6dhxaza18jl6d29yczsqp0nf7lr07avj-python3.11-django-4.2.12/lib/python3.11/site-packages/django/db/models/sql/compiler.py", line 1562, in execute_sql
    cursor.execute(sql, params)
  File "/nix/store/6dhxaza18jl6d29yczsqp0nf7lr07avj-python3.11-django-4.2.12/lib/python3.11/site-packages/django/db/backends/utils.py", line 67, in execute
    return self._execute_with_wrappers(
           ^^^^^^^^^^^^^^^^^^^^^^^^^^^^
  File "/nix/store/6dhxaza18jl6d29yczsqp0nf7lr07avj-python3.11-django-4.2.12/lib/python3.11/site-packages/django/db/backends/utils.py", line 80, in _execute_with_wrappers
    return executor(sql, params, many, context)
           ^^^^^^^^^^^^^^^^^^^^^^^^^^^^^^^^^^^^
  File "/nix/store/6dhxaza18jl6d29yczsqp0nf7lr07avj-python3.11-django-4.2.12/lib/python3.11/site-packages/django/db/backends/utils.py", line 84, in _execute
    with self.db.wrap_database_errors:
  File "/nix/store/6dhxaza18jl6d29yczsqp0nf7lr07avj-python3.11-django-4.2.12/lib/python3.11/site-packages/django/db/utils.py", line 91, in __exit__
    raise dj_exc_value.with_traceback(traceback) from exc_value
  File "/nix/store/6dhxaza18jl6d29yczsqp0nf7lr07avj-python3.11-django-4.2.12/lib/python3.11/site-packages/django/db/backends/utils.py", line 89, in _execute
    return self.cursor.execute(sql, params)
           ^^^^^^^^^^^^^^^^^^^^^^^^^^^^^^^^
django.db.utils.ProgrammingError: relation "django_session" does not exist
LINE 1: ...ession_data", "django_session"."expire_date" FROM "django_se...
                                                             ^


During handling of the above exception, another exception occurred:


During handling of the above exception, another exception occurred:

Traceback (most recent call last):
  File "/nix/store/6dhxaza18jl6d29yczsqp0nf7lr07avj-python3.11-django-4.2.12/lib/python3.11/site-packages/django/db/backends/utils.py", line 89, in _execute
    return self.cursor.execute(sql, params)
           ^^^^^^^^^^^^^^^^^^^^^^^^^^^^^^^^
psycopg2.errors.UndefinedTable: relation "django_session" does not exist
LINE 1: ...ession_data", "django_session"."expire_date" FROM "django_se...
                                                             ^


The above exception was the direct cause of the following exception:

Traceback (most recent call last):
  File "/nix/store/6dhxaza18jl6d29yczsqp0nf7lr07avj-python3.11-django-4.2.12/lib/python3.11/site-packages/django/core/handlers/exception.py", line 55, in inner
    response = get_response(request)
               ^^^^^^^^^^^^^^^^^^^^^
  File "/nix/store/6dhxaza18jl6d29yczsqp0nf7lr07avj-python3.11-django-4.2.12/lib/python3.11/site-packages/django/utils/deprecation.py", line 133, in __call__
    response = self.process_request(request)
               ^^^^^^^^^^^^^^^^^^^^^^^^^^^^^
  File "/nix/store/6dhxaza18jl6d29yczsqp0nf7lr07avj-python3.11-django-4.2.12/lib/python3.11/site-packages/django/middleware/csrf.py", line 408, in process_request
    csrf_secret = self._get_secret(request)
                  ^^^^^^^^^^^^^^^^^^^^^^^^^
  File "/nix/store/6dhxaza18jl6d29yczsqp0nf7lr07avj-python3.11-django-4.2.12/lib/python3.11/site-packages/django/middleware/csrf.py", line 236, in _get_secret
    csrf_secret = request.session.get(CSRF_SESSION_KEY)
                  ^^^^^^^^^^^^^^^^^^^^^^^^^^^^^^^^^^^^^
  File "/nix/store/6dhxaza18jl6d29yczsqp0nf7lr07avj-python3.11-django-4.2.12/lib/python3.11/site-packages/django/contrib/sessions/backends/base.py", line 68, in get
    return self._session.get(key, default)
           ^^^^^^^^^^^^^
  File "/nix/store/6dhxaza18jl6d29yczsqp0nf7lr07avj-python3.11-django-4.2.12/lib/python3.11/site-packages/django/contrib/sessions/backends/base.py", line 192, in _get_session
    self._session_cache = self.load()
                          ^^^^^^^^^^^
  File "/nix/store/6dhxaza18jl6d29yczsqp0nf7lr07avj-python3.11-django-4.2.12/lib/python3.11/site-packages/django/contrib/sessions/backends/db.py", line 42, in load
    s = self._get_session_from_db()
        ^^^^^^^^^^^^^^^^^^^^^^^^^^^
  File "/nix/store/6dhxaza18jl6d29yczsqp0nf7lr07avj-python3.11-django-4.2.12/lib/python3.11/site-packages/django/contrib/sessions/backends/db.py", line 32, in _get_session_from_db
    return self.model.objects.get(
           ^^^^^^^^^^^^^^^^^^^^^^^
  File "/nix/store/6dhxaza18jl6d29yczsqp0nf7lr07avj-python3.11-django-4.2.12/lib/python3.11/site-packages/django/db/models/manager.py", line 87, in manager_method
    return getattr(self.get_queryset(), name)(*args, **kwargs)
           ^^^^^^^^^^^^^^^^^^^^^^^^^^^^^^^^^^^^^^^^^^^^^^^^^^^
  File "/nix/store/6dhxaza18jl6d29yczsqp0nf7lr07avj-python3.11-django-4.2.12/lib/python3.11/site-packages/django/db/models/query.py", line 633, in get
    num = len(clone)
          ^^^^^^^^^^
  File "/nix/store/6dhxaza18jl6d29yczsqp0nf7lr07avj-python3.11-django-4.2.12/lib/python3.11/site-packages/django/db/models/query.py", line 380, in __len__
    self._fetch_all()
  File "/nix/store/6dhxaza18jl6d29yczsqp0nf7lr07avj-python3.11-django-4.2.12/lib/python3.11/site-packages/django/db/models/query.py", line 1881, in _fetch_all
    self._result_cache = list(self._iterable_class(self))
                         ^^^^^^^^^^^^^^^^^^^^^^^^^^^^^^^^
  File "/nix/store/6dhxaza18jl6d29yczsqp0nf7lr07avj-python3.11-django-4.2.12/lib/python3.11/site-packages/django/db/models/query.py", line 91, in __iter__
    results = compiler.execute_sql(
              ^^^^^^^^^^^^^^^^^^^^^
  File "/nix/store/6dhxaza18jl6d29yczsqp0nf7lr07avj-python3.11-django-4.2.12/lib/python3.11/site-packages/django/db/models/sql/compiler.py", line 1562, in execute_sql
    cursor.execute(sql, params)
  File "/nix/store/6dhxaza18jl6d29yczsqp0nf7lr07avj-python3.11-django-4.2.12/lib/python3.11/site-packages/django/db/backends/utils.py", line 67, in execute
    return self._execute_with_wrappers(
           ^^^^^^^^^^^^^^^^^^^^^^^^^^^^
  File "/nix/store/6dhxaza18jl6d29yczsqp0nf7lr07avj-python3.11-django-4.2.12/lib/python3.11/site-packages/django/db/backends/utils.py", line 80, in _execute_with_wrappers
    return executor(sql, params, many, context)
           ^^^^^^^^^^^^^^^^^^^^^^^^^^^^^^^^^^^^
  File "/nix/store/6dhxaza18jl6d29yczsqp0nf7lr07avj-python3.11-django-4.2.12/lib/python3.11/site-packages/django/db/backends/utils.py", line 84, in _execute
    with self.db.wrap_database_errors:
  File "/nix/store/6dhxaza18jl6d29yczsqp0nf7lr07avj-python3.11-django-4.2.12/lib/python3.11/site-packages/django/db/utils.py", line 91, in __exit__
    raise dj_exc_value.with_traceback(traceback) from exc_value
  File "/nix/store/6dhxaza18jl6d29yczsqp0nf7lr07avj-python3.11-django-4.2.12/lib/python3.11/site-packages/django/db/backends/utils.py", line 89, in _execute
    return self.cursor.execute(sql, params)
           ^^^^^^^^^^^^^^^^^^^^^^^^^^^^^^^^
django.db.utils.ProgrammingError: relation "django_session" does not exist
LINE 1: ...ession_data", "django_session"."expire_date" FROM "django_se...
                                                             ^


During handling of the above exception, another exception occurred:

Traceback (most recent call last):
  File "/nix/store/6dhxaza18jl6d29yczsqp0nf7lr07avj-python3.11-django-4.2.12/lib/python3.11/site-packages/django/contrib/sessions/backends/base.py", line 187, in _get_session
    return self._session_cache
           ^^^^^^^^^^^^^^^^^^^
AttributeError: 'SessionStore' object has no attribute '_session_cache'

During handling of the above exception, another exception occurred:

Traceback (most recent call last):
  File "/nix/store/6dhxaza18jl6d29yczsqp0nf7lr07avj-python3.11-django-4.2.12/lib/python3.11/site-packages/django/db/backends/utils.py", line 89, in _execute
    return self.cursor.execute(sql, params)
           ^^^^^^^^^^^^^^^^^^^^^^^^^^^^^^^^
psycopg2.errors.UndefinedTable: relation "django_session" does not exist
LINE 1: ...ession_data", "django_session"."expire_date" FROM "django_se...
                                                             ^


The above exception was the direct cause of the following exception:

Traceback (most recent call last):
Traceback (most recent call last):
  File "/nix/store/6dhxaza18jl6d29yczsqp0nf7lr07avj-python3.11-django-4.2.12/lib/python3.11/site-packages/django/core/handlers/exception.py", line 55, in inner
    response = get_response(request)
               ^^^^^^^^^^^^^^^^^^^^^
  File "/nix/store/6dhxaza18jl6d29yczsqp0nf7lr07avj-python3.11-django-4.2.12/lib/python3.11/site-packages/django/utils/deprecation.py", line 134, in __call__
    response = response or self.get_response(request)
                           ^^^^^^^^^^^^^^^^^^^^^^^^^^
  File "/nix/store/6dhxaza18jl6d29yczsqp0nf7lr07avj-python3.11-django-4.2.12/lib/python3.11/site-packages/django/core/handlers/exception.py", line 57, in inner
    response = response_for_exception(request, exc)
               ^^^^^^^^^^^^^^^^^^^^^^^^^^^^^^^^^^^^
  File "/nix/store/6dhxaza18jl6d29yczsqp0nf7lr07avj-python3.11-django-4.2.12/lib/python3.11/site-packages/django/core/handlers/exception.py", line 140, in response_for_exception
    response = handle_uncaught_exception(
               ^^^^^^^^^^^^^^^^^^^^^^^^^^
  File "/nix/store/6dhxaza18jl6d29yczsqp0nf7lr07avj-python3.11-django-4.2.12/lib/python3.11/site-packages/django/core/handlers/exception.py", line 185, in handle_uncaught_exception
    return callback(request)
           ^^^^^^^^^^^^^^^^^
  File "/nix/store/6dhxaza18jl6d29yczsqp0nf7lr07avj-python3.11-django-4.2.12/lib/python3.11/site-packages/django/utils/decorators.py", line 126, in _wrapper_view
    result = middleware.process_request(request)
             ^^^^^^^^^^^^^^^^^^^^^^^^^^^^^^^^^^^
  File "/nix/store/6dhxaza18jl6d29yczsqp0nf7lr07avj-python3.11-django-4.2.12/lib/python3.11/site-packages/django/contrib/sessions/backends/base.py", line 187, in _get_session
    return self._session_cache
           ^^^^^^^^^^^^^^^^^^^
  File "/nix/store/6dhxaza18jl6d29yczsqp0nf7lr07avj-python3.11-django-4.2.12/lib/python3.11/site-packages/django/middleware/csrf.py", line 408, in process_request
    csrf_secret = self._get_secret(request)
                  ^^^^^^^^^^^^^^^^^^^^^^^^^
  File "/nix/store/6dhxaza18jl6d29yczsqp0nf7lr07avj-python3.11-django-4.2.12/lib/python3.11/site-packages/django/middleware/csrf.py", line 236, in _get_secret
    csrf_secret = request.session.get(CSRF_SESSION_KEY)
                  ^^^^^^^^^^^^^^^^^^^^^^^^^^^^^^^^^^^^^
  File "/nix/store/6dhxaza18jl6d29yczsqp0nf7lr07avj-python3.11-django-4.2.12/lib/python3.11/site-packages/django/contrib/sessions/backends/base.py", line 68, in get
    return self._session.get(key, default)
           ^^^^^^^^^^^^^
  File "/nix/store/6dhxaza18jl6d29yczsqp0nf7lr07avj-python3.11-django-4.2.12/lib/python3.11/site-packages/django/contrib/sessions/backends/base.py", line 192, in _get_session
    self._session_cache = self.load()
                          ^^^^^^^^^^^
  File "/nix/store/6dhxaza18jl6d29yczsqp0nf7lr07avj-python3.11-django-4.2.12/lib/python3.11/site-packages/django/contrib/sessions/backends/db.py", line 42, in load
    s = self._get_session_from_db()
        ^^^^^^^^^^^^^^^^^^^^^^^^^^^
  File "/nix/store/6dhxaza18jl6d29yczsqp0nf7lr07avj-python3.11-django-4.2.12/lib/python3.11/site-packages/django/contrib/sessions/backends/db.py", line 32, in _get_session_from_db
    return self.model.objects.get(
           ^^^^^^^^^^^^^^^^^^^^^^^
  File "/nix/store/6dhxaza18jl6d29yczsqp0nf7lr07avj-python3.11-django-4.2.12/lib/python3.11/site-packages/django/db/models/manager.py", line 87, in manager_method
    return getattr(self.get_queryset(), name)(*args, **kwargs)
           ^^^^^^^^^^^^^^^^^^^^^^^^^^^^^^^^^^^^^^^^^^^^^^^^^^^
  File "/nix/store/6dhxaza18jl6d29yczsqp0nf7lr07avj-python3.11-django-4.2.12/lib/python3.11/site-packages/django/db/models/query.py", line 633, in get
    num = len(clone)
          ^^^^^^^^^^
  File "/nix/store/6dhxaza18jl6d29yczsqp0nf7lr07avj-python3.11-django-4.2.12/lib/python3.11/site-packages/django/db/models/query.py", line 380, in __len__
    self._fetch_all()
  File "/nix/store/6dhxaza18jl6d29yczsqp0nf7lr07avj-python3.11-django-4.2.12/lib/python3.11/site-packages/django/db/models/query.py", line 1881, in _fetch_all
    self._result_cache = list(self._iterable_class(self))
                         ^^^^^^^^^^^^^^^^^^^^^^^^^^^^^^^^
  File "/nix/store/6dhxaza18jl6d29yczsqp0nf7lr07avj-python3.11-django-4.2.12/lib/python3.11/site-packages/django/db/models/query.py", line 91, in __iter__
    results = compiler.execute_sql(
              ^^^^^^^^^^^^^^^^^^^^^
  File "/nix/store/6dhxaza18jl6d29yczsqp0nf7lr07avj-python3.11-django-4.2.12/lib/python3.11/site-packages/django/db/models/sql/compiler.py", line 1562, in execute_sql
    cursor.execute(sql, params)
  File "/nix/store/6dhxaza18jl6d29yczsqp0nf7lr07avj-python3.11-django-4.2.12/lib/python3.11/site-packages/django/db/backends/utils.py", line 67, in execute
    return self._execute_with_wrappers(
           ^^^^^^^^^^^^^^^^^^^^^^^^^^^^
  File "/nix/store/6dhxaza18jl6d29yczsqp0nf7lr07avj-python3.11-django-4.2.12/lib/python3.11/site-packages/django/db/backends/utils.py", line 80, in _execute_with_wrappers
    return executor(sql, params, many, context)
           ^^^^^^^^^^^^^^^^^^^^^^^^^^^^^^^^^^^^
  File "/nix/store/6dhxaza18jl6d29yczsqp0nf7lr07avj-python3.11-django-4.2.12/lib/python3.11/site-packages/django/db/backends/utils.py", line 84, in _execute
    with self.db.wrap_database_errors:
  File "/nix/store/6dhxaza18jl6d29yczsqp0nf7lr07avj-python3.11-django-4.2.12/lib/python3.11/site-packages/django/db/utils.py", line 91, in __exit__
    raise dj_exc_value.with_traceback(traceback) from exc_value
  File "/nix/store/6dhxaza18jl6d29yczsqp0nf7lr07avj-python3.11-django-4.2.12/lib/python3.11/site-packages/django/db/backends/utils.py", line 89, in _execute
    return self.cursor.execute(sql, params)
           ^^^^^^^^^^^^^^^^^^^^^^^^^^^^^^^^
django.db.utils.ProgrammingError: relation "django_session" does not exist
LINE 1: ...ession_data", "django_session"."expire_date" FROM "django_se...
                                                             ^


During handling of the above exception, another exception occurred:

AttributeError: 'SessionStore' object has no attribute '_session_cache'

During handling of the above exception, another exception occurred:

Traceback (most recent call last):
  File "/nix/store/6dhxaza18jl6d29yczsqp0nf7lr07avj-python3.11-django-4.2.12/lib/python3.11/site-packages/django/db/backends/utils.py", line 89, in _execute
    return self.cursor.execute(sql, params)
           ^^^^^^^^^^^^^^^^^^^^^^^^^^^^^^^^
psycopg2.errors.UndefinedTable: relation "django_session" does not exist
LINE 1: ...ession_data", "django_session"."expire_date" FROM "django_se...
                                                             ^


The above exception was the direct cause of the following exception:

Traceback (most recent call last):
  File "/nix/store/6dhxaza18jl6d29yczsqp0nf7lr07avj-python3.11-django-4.2.12/lib/python3.11/site-packages/django/core/handlers/exception.py", line 55, in inner
    response = get_response(request)
               ^^^^^^^^^^^^^^^^^^^^^
  File "/nix/store/6dhxaza18jl6d29yczsqp0nf7lr07avj-python3.11-django-4.2.12/lib/python3.11/site-packages/django/utils/deprecation.py", line 134, in __call__
    response = response or self.get_response(request)
                           ^^^^^^^^^^^^^^^^^^^^^^^^^^
Traceback (most recent call last):
  File "/nix/store/6dhxaza18jl6d29yczsqp0nf7lr07avj-python3.11-django-4.2.12/lib/python3.11/site-packages/django/core/handlers/exception.py", line 57, in inner
    response = response_for_exception(request, exc)
               ^^^^^^^^^^^^^^^^^^^^^^^^^^^^^^^^^^^^
  File "/nix/store/6dhxaza18jl6d29yczsqp0nf7lr07avj-python3.11-django-4.2.12/lib/python3.11/site-packages/django/contrib/sessions/backends/base.py", line 187, in _get_session
    return self._session_cache
           ^^^^^^^^^^^^^^^^^^^
  File "/nix/store/6dhxaza18jl6d29yczsqp0nf7lr07avj-python3.11-django-4.2.12/lib/python3.11/site-packages/django/core/handlers/exception.py", line 140, in response_for_exception
    response = handle_uncaught_exception(
               ^^^^^^^^^^^^^^^^^^^^^^^^^^
  File "/nix/store/6dhxaza18jl6d29yczsqp0nf7lr07avj-python3.11-django-4.2.12/lib/python3.11/site-packages/django/core/handlers/exception.py", line 185, in handle_uncaught_exception
    return callback(request)
           ^^^^^^^^^^^^^^^^^
  File "/nix/store/6dhxaza18jl6d29yczsqp0nf7lr07avj-python3.11-django-4.2.12/lib/python3.11/site-packages/django/utils/decorators.py", line 126, in _wrapper_view
    result = middleware.process_request(request)
             ^^^^^^^^^^^^^^^^^^^^^^^^^^^^^^^^^^^
  File "/nix/store/6dhxaza18jl6d29yczsqp0nf7lr07avj-python3.11-django-4.2.12/lib/python3.11/site-packages/django/middleware/csrf.py", line 408, in process_request
    csrf_secret = self._get_secret(request)
                  ^^^^^^^^^^^^^^^^^^^^^^^^^
  File "/nix/store/6dhxaza18jl6d29yczsqp0nf7lr07avj-python3.11-django-4.2.12/lib/python3.11/site-packages/django/middleware/csrf.py", line 236, in _get_secret
    csrf_secret = request.session.get(CSRF_SESSION_KEY)
                  ^^^^^^^^^^^^^^^^^^^^^^^^^^^^^^^^^^^^^
  File "/nix/store/6dhxaza18jl6d29yczsqp0nf7lr07avj-python3.11-django-4.2.12/lib/python3.11/site-packages/django/contrib/sessions/backends/base.py", line 68, in get
    return self._session.get(key, default)
           ^^^^^^^^^^^^^
AttributeError: 'SessionStore' object has no attribute '_session_cache'

During handling of the above exception, another exception occurred:

Traceback (most recent call last):
  File "/nix/store/6dhxaza18jl6d29yczsqp0nf7lr07avj-python3.11-django-4.2.12/lib/python3.11/site-packages/django/db/backends/utils.py", line 89, in _execute
    return self.cursor.execute(sql, params)
           ^^^^^^^^^^^^^^^^^^^^^^^^^^^^^^^^
psycopg2.errors.UndefinedTable: relation "django_session" does not exist
LINE 1: ...ession_data", "django_session"."expire_date" FROM "django_se...
                                                             ^


The above exception was the direct cause of the following exception:

Traceback (most recent call last):
  File "/nix/store/6dhxaza18jl6d29yczsqp0nf7lr07avj-python3.11-django-4.2.12/lib/python3.11/site-packages/django/contrib/sessions/backends/base.py", line 192, in _get_session
    self._session_cache = self.load()
                          ^^^^^^^^^^^
  File "/nix/store/6dhxaza18jl6d29yczsqp0nf7lr07avj-python3.11-django-4.2.12/lib/python3.11/site-packages/django/contrib/sessions/backends/db.py", line 42, in load
    s = self._get_session_from_db()
        ^^^^^^^^^^^^^^^^^^^^^^^^^^^
  File "/nix/store/6dhxaza18jl6d29yczsqp0nf7lr07avj-python3.11-django-4.2.12/lib/python3.11/site-packages/django/contrib/sessions/backends/db.py", line 32, in _get_session_from_db
    return self.model.objects.get(
           ^^^^^^^^^^^^^^^^^^^^^^^
  File "/nix/store/6dhxaza18jl6d29yczsqp0nf7lr07avj-python3.11-django-4.2.12/lib/python3.11/site-packages/django/db/models/manager.py", line 87, in manager_method
    return getattr(self.get_queryset(), name)(*args, **kwargs)
           ^^^^^^^^^^^^^^^^^^^^^^^^^^^^^^^^^^^^^^^^^^^^^^^^^^^
  File "/nix/store/6dhxaza18jl6d29yczsqp0nf7lr07avj-python3.11-django-4.2.12/lib/python3.11/site-packages/django/db/models/query.py", line 633, in get
    num = len(clone)
          ^^^^^^^^^^
  File "/nix/store/6dhxaza18jl6d29yczsqp0nf7lr07avj-python3.11-django-4.2.12/lib/python3.11/site-packages/django/db/models/query.py", line 380, in __len__
    self._fetch_all()
  File "/nix/store/6dhxaza18jl6d29yczsqp0nf7lr07avj-python3.11-django-4.2.12/lib/python3.11/site-packages/django/db/models/query.py", line 1881, in _fetch_all
    self._result_cache = list(self._iterable_class(self))
                         ^^^^^^^^^^^^^^^^^^^^^^^^^^^^^^^^
  File "/nix/store/6dhxaza18jl6d29yczsqp0nf7lr07avj-python3.11-django-4.2.12/lib/python3.11/site-packages/django/db/models/query.py", line 91, in __iter__
    results = compiler.execute_sql(
              ^^^^^^^^^^^^^^^^^^^^^
  File "/nix/store/6dhxaza18jl6d29yczsqp0nf7lr07avj-python3.11-django-4.2.12/lib/python3.11/site-packages/django/db/models/sql/compiler.py", line 1562, in execute_sql
    cursor.execute(sql, params)
  File "/nix/store/6dhxaza18jl6d29yczsqp0nf7lr07avj-python3.11-django-4.2.12/lib/python3.11/site-packages/django/db/backends/utils.py", line 67, in execute
    return self._execute_with_wrappers(
           ^^^^^^^^^^^^^^^^^^^^^^^^^^^^
  File "/nix/store/6dhxaza18jl6d29yczsqp0nf7lr07avj-python3.11-django-4.2.12/lib/python3.11/site-packages/django/db/backends/utils.py", line 80, in _execute_with_wrappers
    return executor(sql, params, many, context)
           ^^^^^^^^^^^^^^^^^^^^^^^^^^^^^^^^^^^^
  File "/nix/store/6dhxaza18jl6d29yczsqp0nf7lr07avj-python3.11-django-4.2.12/lib/python3.11/site-packages/django/db/backends/utils.py", line 84, in _execute
    with self.db.wrap_database_errors:
  File "/nix/store/6dhxaza18jl6d29yczsqp0nf7lr07avj-python3.11-django-4.2.12/lib/python3.11/site-packages/django/db/utils.py", line 91, in __exit__
    raise dj_exc_value.with_traceback(traceback) from exc_value
  File "/nix/store/6dhxaza18jl6d29yczsqp0nf7lr07avj-python3.11-django-4.2.12/lib/python3.11/site-packages/django/db/backends/utils.py", line 89, in _execute
    return self.cursor.execute(sql, params)
           ^^^^^^^^^^^^^^^^^^^^^^^^^^^^^^^^
django.db.utils.ProgrammingError: relation "django_session" does not exist
LINE 1: ...ession_data", "django_session"."expire_date" FROM "django_se...
                                                             ^


During handling of the above exception, another exception occurred:

Traceback (most recent call last):
  File "/nix/store/6dhxaza18jl6d29yczsqp0nf7lr07avj-python3.11-django-4.2.12/lib/python3.11/site-packages/django/contrib/sessions/backends/base.py", line 187, in _get_session
    return self._session_cache
           ^^^^^^^^^^^^^^^^^^^
AttributeError: 'SessionStore' object has no attribute '_session_cache'

During handling of the above exception, another exception occurred:

Traceback (most recent call last):
  File "/nix/store/6dhxaza18jl6d29yczsqp0nf7lr07avj-python3.11-django-4.2.12/lib/python3.11/site-packages/django/db/backends/utils.py", line 89, in _execute
    return self.cursor.execute(sql, params)
           ^^^^^^^^^^^^^^^^^^^^^^^^^^^^^^^^
psycopg2.errors.UndefinedTable: relation "django_session" does not exist
LINE 1: ...ession_data", "django_session"."expire_date" FROM "django_se...
                                                             ^


The above exception was the direct cause of the following exception:

Traceback (most recent call last):
  File "/nix/store/6dhxaza18jl6d29yczsqp0nf7lr07avj-python3.11-django-4.2.12/lib/python3.11/site-packages/django/core/handlers/exception.py", line 55, in inner
    response = get_response(request)
               ^^^^^^^^^^^^^^^^^^^^^
  File "/nix/store/6dhxaza18jl6d29yczsqp0nf7lr07avj-python3.11-django-4.2.12/lib/python3.11/site-packages/django/utils/deprecation.py", line 134, in __call__
    response = response or self.get_response(request)
                           ^^^^^^^^^^^^^^^^^^^^^^^^^^
  File "/nix/store/6dhxaza18jl6d29yczsqp0nf7lr07avj-python3.11-django-4.2.12/lib/python3.11/site-packages/django/core/handlers/exception.py", line 57, in inner
    response = response_for_exception(request, exc)
               ^^^^^^^^^^^^^^^^^^^^^^^^^^^^^^^^^^^^
  File "/nix/store/6dhxaza18jl6d29yczsqp0nf7lr07avj-python3.11-django-4.2.12/lib/python3.11/site-packages/django/core/handlers/exception.py", line 140, in response_for_exception
    response = handle_uncaught_exception(
               ^^^^^^^^^^^^^^^^^^^^^^^^^^
  File "/nix/store/6dhxaza18jl6d29yczsqp0nf7lr07avj-python3.11-django-4.2.12/lib/python3.11/site-packages/django/core/handlers/exception.py", line 185, in handle_uncaught_exception
    return callback(request)
           ^^^^^^^^^^^^^^^^^
  File "/nix/store/6dhxaza18jl6d29yczsqp0nf7lr07avj-python3.11-django-4.2.12/lib/python3.11/site-packages/django/utils/decorators.py", line 126, in _wrapper_view
    result = middleware.process_request(request)
             ^^^^^^^^^^^^^^^^^^^^^^^^^^^^^^^^^^^
  File "/nix/store/6dhxaza18jl6d29yczsqp0nf7lr07avj-python3.11-django-4.2.12/lib/python3.11/site-packages/django/middleware/csrf.py", line 408, in process_request
    csrf_secret = self._get_secret(request)
                  ^^^^^^^^^^^^^^^^^^^^^^^^^
  File "/nix/store/6dhxaza18jl6d29yczsqp0nf7lr07avj-python3.11-django-4.2.12/lib/python3.11/site-packages/django/middleware/csrf.py", line 236, in _get_secret
    csrf_secret = request.session.get(CSRF_SESSION_KEY)
                  ^^^^^^^^^^^^^^^^^^^^^^^^^^^^^^^^^^^^^
  File "/nix/store/6dhxaza18jl6d29yczsqp0nf7lr07avj-python3.11-django-4.2.12/lib/python3.11/site-packages/django/contrib/sessions/backends/base.py", line 68, in get
    return self._session.get(key, default)
           ^^^^^^^^^^^^^
  File "/nix/store/6dhxaza18jl6d29yczsqp0nf7lr07avj-python3.11-django-4.2.12/lib/python3.11/site-packages/django/contrib/sessions/backends/base.py", line 192, in _get_session
    self._session_cache = self.load()
                          ^^^^^^^^^^^
  File "/nix/store/6dhxaza18jl6d29yczsqp0nf7lr07avj-python3.11-django-4.2.12/lib/python3.11/site-packages/django/contrib/sessions/backends/db.py", line 42, in load
    s = self._get_session_from_db()
        ^^^^^^^^^^^^^^^^^^^^^^^^^^^
  File "/nix/store/6dhxaza18jl6d29yczsqp0nf7lr07avj-python3.11-django-4.2.12/lib/python3.11/site-packages/django/contrib/sessions/backends/db.py", line 32, in _get_session_from_db
    return self.model.objects.get(
           ^^^^^^^^^^^^^^^^^^^^^^^
  File "/nix/store/6dhxaza18jl6d29yczsqp0nf7lr07avj-python3.11-django-4.2.12/lib/python3.11/site-packages/django/db/models/manager.py", line 87, in manager_method
    return getattr(self.get_queryset(), name)(*args, **kwargs)
           ^^^^^^^^^^^^^^^^^^^^^^^^^^^^^^^^^^^^^^^^^^^^^^^^^^^
  File "/nix/store/6dhxaza18jl6d29yczsqp0nf7lr07avj-python3.11-django-4.2.12/lib/python3.11/site-packages/django/db/models/query.py", line 633, in get
    num = len(clone)
          ^^^^^^^^^^
  File "/nix/store/6dhxaza18jl6d29yczsqp0nf7lr07avj-python3.11-django-4.2.12/lib/python3.11/site-packages/django/db/models/query.py", line 380, in __len__
    self._fetch_all()
  File "/nix/store/6dhxaza18jl6d29yczsqp0nf7lr07avj-python3.11-django-4.2.12/lib/python3.11/site-packages/django/db/models/query.py", line 1881, in _fetch_all
    self._result_cache = list(self._iterable_class(self))
                         ^^^^^^^^^^^^^^^^^^^^^^^^^^^^^^^^
  File "/nix/store/6dhxaza18jl6d29yczsqp0nf7lr07avj-python3.11-django-4.2.12/lib/python3.11/site-packages/django/db/models/query.py", line 91, in __iter__
    results = compiler.execute_sql(
              ^^^^^^^^^^^^^^^^^^^^^
  File "/nix/store/6dhxaza18jl6d29yczsqp0nf7lr07avj-python3.11-django-4.2.12/lib/python3.11/site-packages/django/db/models/sql/compiler.py", line 1562, in execute_sql
    cursor.execute(sql, params)
  File "/nix/store/6dhxaza18jl6d29yczsqp0nf7lr07avj-python3.11-django-4.2.12/lib/python3.11/site-packages/django/db/backends/utils.py", line 67, in execute
    return self._execute_with_wrappers(
           ^^^^^^^^^^^^^^^^^^^^^^^^^^^^
  File "/nix/store/6dhxaza18jl6d29yczsqp0nf7lr07avj-python3.11-django-4.2.12/lib/python3.11/site-packages/django/db/backends/utils.py", line 80, in _execute_with_wrappers
    return executor(sql, params, many, context)
           ^^^^^^^^^^^^^^^^^^^^^^^^^^^^^^^^^^^^
  File "/nix/store/6dhxaza18jl6d29yczsqp0nf7lr07avj-python3.11-django-4.2.12/lib/python3.11/site-packages/django/db/backends/utils.py", line 84, in _execute
    with self.db.wrap_database_errors:
  File "/nix/store/6dhxaza18jl6d29yczsqp0nf7lr07avj-python3.11-django-4.2.12/lib/python3.11/site-packages/django/db/utils.py", line 91, in __exit__
    raise dj_exc_value.with_traceback(traceback) from exc_value
  File "/nix/store/6dhxaza18jl6d29yczsqp0nf7lr07avj-python3.11-django-4.2.12/lib/python3.11/site-packages/django/db/backends/utils.py", line 89, in _execute
    return self.cursor.execute(sql, params)
           ^^^^^^^^^^^^^^^^^^^^^^^^^^^^^^^^
django.db.utils.ProgrammingError: relation "django_session" does not exist
LINE 1: ...ession_data", "django_session"."expire_date" FROM "django_se...
                                                             ^


During handling of the above exception, another exception occurred:

Traceback (most recent call last):
  File "/nix/store/6dhxaza18jl6d29yczsqp0nf7lr07avj-python3.11-django-4.2.12/lib/python3.11/site-packages/django/contrib/sessions/backends/base.py", line 187, in _get_session
    return self._session_cache
           ^^^^^^^^^^^^^^^^^^^
AttributeError: 'SessionStore' object has no attribute '_session_cache'

During handling of the above exception, another exception occurred:

Traceback (most recent call last):
  File "/nix/store/6dhxaza18jl6d29yczsqp0nf7lr07avj-python3.11-django-4.2.12/lib/python3.11/site-packages/django/db/backends/utils.py", line 89, in _execute
    return self.cursor.execute(sql, params)
           ^^^^^^^^^^^^^^^^^^^^^^^^^^^^^^^^
psycopg2.errors.UndefinedTable: relation "django_session" does not exist
LINE 1: ...ession_data", "django_session"."expire_date" FROM "django_se...
                                                             ^


The above exception was the direct cause of the following exception:

Traceback (most recent call last):
  File "/nix/store/6dhxaza18jl6d29yczsqp0nf7lr07avj-python3.11-django-4.2.12/lib/python3.11/site-packages/django/core/handlers/exception.py", line 55, in inner
    response = get_response(request)
               ^^^^^^^^^^^^^^^^^^^^^
  File "/nix/store/6dhxaza18jl6d29yczsqp0nf7lr07avj-python3.11-django-4.2.12/lib/python3.11/site-packages/django/utils/deprecation.py", line 134, in __call__
    response = response or self.get_response(request)
                           ^^^^^^^^^^^^^^^^^^^^^^^^^^
  File "/nix/store/6dhxaza18jl6d29yczsqp0nf7lr07avj-python3.11-django-4.2.12/lib/python3.11/site-packages/django/core/handlers/exception.py", line 57, in inner
    response = response_for_exception(request, exc)
               ^^^^^^^^^^^^^^^^^^^^^^^^^^^^^^^^^^^^
  File "/nix/store/6dhxaza18jl6d29yczsqp0nf7lr07avj-python3.11-django-4.2.12/lib/python3.11/site-packages/django/core/handlers/exception.py", line 140, in response_for_exception
    response = handle_uncaught_exception(
               ^^^^^^^^^^^^^^^^^^^^^^^^^^
  File "/nix/store/6dhxaza18jl6d29yczsqp0nf7lr07avj-python3.11-django-4.2.12/lib/python3.11/site-packages/django/core/handlers/exception.py", line 185, in handle_uncaught_exception
    return callback(request)
           ^^^^^^^^^^^^^^^^^
  File "/nix/store/6dhxaza18jl6d29yczsqp0nf7lr07avj-python3.11-django-4.2.12/lib/python3.11/site-packages/django/utils/decorators.py", line 126, in _wrapper_view
    result = middleware.process_request(request)
             ^^^^^^^^^^^^^^^^^^^^^^^^^^^^^^^^^^^
  File "/nix/store/6dhxaza18jl6d29yczsqp0nf7lr07avj-python3.11-django-4.2.12/lib/python3.11/site-packages/django/middleware/csrf.py", line 408, in process_request
    csrf_secret = self._get_secret(request)
                  ^^^^^^^^^^^^^^^^^^^^^^^^^
  File "/nix/store/6dhxaza18jl6d29yczsqp0nf7lr07avj-python3.11-django-4.2.12/lib/python3.11/site-packages/django/middleware/csrf.py", line 236, in _get_secret
    csrf_secret = request.session.get(CSRF_SESSION_KEY)
                  ^^^^^^^^^^^^^^^^^^^^^^^^^^^^^^^^^^^^^
  File "/nix/store/6dhxaza18jl6d29yczsqp0nf7lr07avj-python3.11-django-4.2.12/lib/python3.11/site-packages/django/contrib/sessions/backends/base.py", line 68, in get
    return self._session.get(key, default)
           ^^^^^^^^^^^^^
  File "/nix/store/6dhxaza18jl6d29yczsqp0nf7lr07avj-python3.11-django-4.2.12/lib/python3.11/site-packages/django/contrib/sessions/backends/base.py", line 192, in _get_session
    self._session_cache = self.load()
                          ^^^^^^^^^^^
  File "/nix/store/6dhxaza18jl6d29yczsqp0nf7lr07avj-python3.11-django-4.2.12/lib/python3.11/site-packages/django/contrib/sessions/backends/db.py", line 42, in load
    s = self._get_session_from_db()
        ^^^^^^^^^^^^^^^^^^^^^^^^^^^
  File "/nix/store/6dhxaza18jl6d29yczsqp0nf7lr07avj-python3.11-django-4.2.12/lib/python3.11/site-packages/django/contrib/sessions/backends/db.py", line 32, in _get_session_from_db
    return self.model.objects.get(
           ^^^^^^^^^^^^^^^^^^^^^^^
  File "/nix/store/6dhxaza18jl6d29yczsqp0nf7lr07avj-python3.11-django-4.2.12/lib/python3.11/site-packages/django/db/models/manager.py", line 87, in manager_method
    return getattr(self.get_queryset(), name)(*args, **kwargs)
           ^^^^^^^^^^^^^^^^^^^^^^^^^^^^^^^^^^^^^^^^^^^^^^^^^^^
  File "/nix/store/6dhxaza18jl6d29yczsqp0nf7lr07avj-python3.11-django-4.2.12/lib/python3.11/site-packages/django/db/models/query.py", line 633, in get
    num = len(clone)
          ^^^^^^^^^^
  File "/nix/store/6dhxaza18jl6d29yczsqp0nf7lr07avj-python3.11-django-4.2.12/lib/python3.11/site-packages/django/db/models/query.py", line 380, in __len__
    self._fetch_all()
  File "/nix/store/6dhxaza18jl6d29yczsqp0nf7lr07avj-python3.11-django-4.2.12/lib/python3.11/site-packages/django/db/models/query.py", line 1881, in _fetch_all
    self._result_cache = list(self._iterable_class(self))
                         ^^^^^^^^^^^^^^^^^^^^^^^^^^^^^^^^
  File "/nix/store/6dhxaza18jl6d29yczsqp0nf7lr07avj-python3.11-django-4.2.12/lib/python3.11/site-packages/django/db/models/query.py", line 91, in __iter__
    results = compiler.execute_sql(
              ^^^^^^^^^^^^^^^^^^^^^
  File "/nix/store/6dhxaza18jl6d29yczsqp0nf7lr07avj-python3.11-django-4.2.12/lib/python3.11/site-packages/django/db/models/sql/compiler.py", line 1562, in execute_sql
    cursor.execute(sql, params)
  File "/nix/store/6dhxaza18jl6d29yczsqp0nf7lr07avj-python3.11-django-4.2.12/lib/python3.11/site-packages/django/db/backends/utils.py", line 67, in execute
    return self._execute_with_wrappers(
           ^^^^^^^^^^^^^^^^^^^^^^^^^^^^
  File "/nix/store/6dhxaza18jl6d29yczsqp0nf7lr07avj-python3.11-django-4.2.12/lib/python3.11/site-packages/django/db/backends/utils.py", line 80, in _execute_with_wrappers
    return executor(sql, params, many, context)
           ^^^^^^^^^^^^^^^^^^^^^^^^^^^^^^^^^^^^
  File "/nix/store/6dhxaza18jl6d29yczsqp0nf7lr07avj-python3.11-django-4.2.12/lib/python3.11/site-packages/django/db/backends/utils.py", line 84, in _execute
    with self.db.wrap_database_errors:
  File "/nix/store/6dhxaza18jl6d29yczsqp0nf7lr07avj-python3.11-django-4.2.12/lib/python3.11/site-packages/django/db/utils.py", line 91, in __exit__
    raise dj_exc_value.with_traceback(traceback) from exc_value
  File "/nix/store/6dhxaza18jl6d29yczsqp0nf7lr07avj-python3.11-django-4.2.12/lib/python3.11/site-packages/django/db/backends/utils.py", line 89, in _execute
    return self.cursor.execute(sql, params)
           ^^^^^^^^^^^^^^^^^^^^^^^^^^^^^^^^
django.db.utils.ProgrammingError: relation "django_session" does not exist
LINE 1: ...ession_data", "django_session"."expire_date" FROM "django_se...
                                                             ^


During handling of the above exception, another exception occurred:

Traceback (most recent call last):
  File "/nix/store/6dhxaza18jl6d29yczsqp0nf7lr07avj-python3.11-django-4.2.12/lib/python3.11/site-packages/django/contrib/sessions/backends/base.py", line 187, in _get_session
    return self._session_cache
           ^^^^^^^^^^^^^^^^^^^
AttributeError: 'SessionStore' object has no attribute '_session_cache'

During handling of the above exception, another exception occurred:

Traceback (most recent call last):
  File "/nix/store/6dhxaza18jl6d29yczsqp0nf7lr07avj-python3.11-django-4.2.12/lib/python3.11/site-packages/django/db/backends/utils.py", line 89, in _execute
    return self.cursor.execute(sql, params)
           ^^^^^^^^^^^^^^^^^^^^^^^^^^^^^^^^
psycopg2.errors.UndefinedTable: relation "django_session" does not exist
LINE 1: ...ession_data", "django_session"."expire_date" FROM "django_se...
                                                             ^


The above exception was the direct cause of the following exception:

Traceback (most recent call last):
  File "/nix/store/clx0mcir7qw8zk36zbr4jra789g3knf6-python3-3.11.10/lib/python3.11/wsgiref/handlers.py", line 137, in run
    self.result = application(self.environ, self.start_response)
                  ^^^^^^^^^^^^^^^^^^^^^^^^^^^^^^^^^^^^^^^^^^^^^^
  File "/nix/store/6dhxaza18jl6d29yczsqp0nf7lr07avj-python3.11-django-4.2.12/lib/python3.11/site-packages/django/core/handlers/wsgi.py", line 124, in __call__
    response = self.get_response(request)
               ^^^^^^^^^^^^^^^^^^^^^^^^^^
  File "/nix/store/6dhxaza18jl6d29yczsqp0nf7lr07avj-python3.11-django-4.2.12/lib/python3.11/site-packages/django/core/handlers/base.py", line 140, in get_response
    response = self._middleware_chain(request)
               ^^^^^^^^^^^^^^^^^^^^^^^^^^^^^^^
  File "/nix/store/6dhxaza18jl6d29yczsqp0nf7lr07avj-python3.11-django-4.2.12/lib/python3.11/site-packages/django/core/handlers/exception.py", line 57, in inner
    response = response_for_exception(request, exc)
               ^^^^^^^^^^^^^^^^^^^^^^^^^^^^^^^^^^^^
  File "/nix/store/6dhxaza18jl6d29yczsqp0nf7lr07avj-python3.11-django-4.2.12/lib/python3.11/site-packages/django/core/handlers/exception.py", line 140, in response_for_exception
    response = handle_uncaught_exception(
               ^^^^^^^^^^^^^^^^^^^^^^^^^^
  File "/nix/store/6dhxaza18jl6d29yczsqp0nf7lr07avj-python3.11-django-4.2.12/lib/python3.11/site-packages/django/core/handlers/exception.py", line 185, in handle_uncaught_exception
    return callback(request)
           ^^^^^^^^^^^^^^^^^
  File "/nix/store/6dhxaza18jl6d29yczsqp0nf7lr07avj-python3.11-django-4.2.12/lib/python3.11/site-packages/django/utils/decorators.py", line 126, in _wrapper_view
    result = middleware.process_request(request)
             ^^^^^^^^^^^^^^^^^^^^^^^^^^^^^^^^^^^
  File "/nix/store/6dhxaza18jl6d29yczsqp0nf7lr07avj-python3.11-django-4.2.12/lib/python3.11/site-packages/django/middleware/csrf.py", line 408, in process_request
    csrf_secret = self._get_secret(request)
                  ^^^^^^^^^^^^^^^^^^^^^^^^^
  File "/nix/store/6dhxaza18jl6d29yczsqp0nf7lr07avj-python3.11-django-4.2.12/lib/python3.11/site-packages/django/middleware/csrf.py", line 236, in _get_secret
    csrf_secret = request.session.get(CSRF_SESSION_KEY)
                  ^^^^^^^^^^^^^^^^^^^^^^^^^^^^^^^^^^^^^
  File "/nix/store/6dhxaza18jl6d29yczsqp0nf7lr07avj-python3.11-django-4.2.12/lib/python3.11/site-packages/django/contrib/sessions/backends/base.py", line 68, in get
    return self._session.get(key, default)
           ^^^^^^^^^^^^^
  File "/nix/store/6dhxaza18jl6d29yczsqp0nf7lr07avj-python3.11-django-4.2.12/lib/python3.11/site-packages/django/contrib/sessions/backends/base.py", line 192, in _get_session
    self._session_cache = self.load()
                          ^^^^^^^^^^^
  File "/nix/store/6dhxaza18jl6d29yczsqp0nf7lr07avj-python3.11-django-4.2.12/lib/python3.11/site-packages/django/contrib/sessions/backends/db.py", line 42, in load
    s = self._get_session_from_db()
        ^^^^^^^^^^^^^^^^^^^^^^^^^^^
  File "/nix/store/6dhxaza18jl6d29yczsqp0nf7lr07avj-python3.11-django-4.2.12/lib/python3.11/site-packages/django/contrib/sessions/backends/db.py", line 32, in _get_session_from_db
    return self.model.objects.get(
           ^^^^^^^^^^^^^^^^^^^^^^^
  File "/nix/store/6dhxaza18jl6d29yczsqp0nf7lr07avj-python3.11-django-4.2.12/lib/python3.11/site-packages/django/db/models/manager.py", line 87, in manager_method
    return getattr(self.get_queryset(), name)(*args, **kwargs)
           ^^^^^^^^^^^^^^^^^^^^^^^^^^^^^^^^^^^^^^^^^^^^^^^^^^^
  File "/nix/store/6dhxaza18jl6d29yczsqp0nf7lr07avj-python3.11-django-4.2.12/lib/python3.11/site-packages/django/db/models/query.py", line 633, in get
    num = len(clone)
          ^^^^^^^^^^
  File "/nix/store/6dhxaza18jl6d29yczsqp0nf7lr07avj-python3.11-django-4.2.12/lib/python3.11/site-packages/django/db/models/query.py", line 380, in __len__
    self._fetch_all()
  File "/nix/store/6dhxaza18jl6d29yczsqp0nf7lr07avj-python3.11-django-4.2.12/lib/python3.11/site-packages/django/db/models/query.py", line 1881, in _fetch_all
    self._result_cache = list(self._iterable_class(self))
                         ^^^^^^^^^^^^^^^^^^^^^^^^^^^^^^^^
  File "/nix/store/6dhxaza18jl6d29yczsqp0nf7lr07avj-python3.11-django-4.2.12/lib/python3.11/site-packages/django/db/models/query.py", line 91, in __iter__
    results = compiler.execute_sql(
              ^^^^^^^^^^^^^^^^^^^^^
  File "/nix/store/6dhxaza18jl6d29yczsqp0nf7lr07avj-python3.11-django-4.2.12/lib/python3.11/site-packages/django/db/models/sql/compiler.py", line 1562, in execute_sql
    cursor.execute(sql, params)
  File "/nix/store/6dhxaza18jl6d29yczsqp0nf7lr07avj-python3.11-django-4.2.12/lib/python3.11/site-packages/django/db/backends/utils.py", line 67, in execute
    return self._execute_with_wrappers(
           ^^^^^^^^^^^^^^^^^^^^^^^^^^^^
  File "/nix/store/6dhxaza18jl6d29yczsqp0nf7lr07avj-python3.11-django-4.2.12/lib/python3.11/site-packages/django/db/backends/utils.py", line 80, in _execute_with_wrappers
    return executor(sql, params, many, context)
           ^^^^^^^^^^^^^^^^^^^^^^^^^^^^^^^^^^^^
  File "/nix/store/6dhxaza18jl6d29yczsqp0nf7lr07avj-python3.11-django-4.2.12/lib/python3.11/site-packages/django/db/backends/utils.py", line 84, in _execute
    with self.db.wrap_database_errors:
  File "/nix/store/6dhxaza18jl6d29yczsqp0nf7lr07avj-python3.11-django-4.2.12/lib/python3.11/site-packages/django/db/utils.py", line 91, in __exit__
    raise dj_exc_value.with_traceback(traceback) from exc_value
  File "/nix/store/6dhxaza18jl6d29yczsqp0nf7lr07avj-python3.11-django-4.2.12/lib/python3.11/site-packages/django/db/backends/utils.py", line 89, in _execute
    return self.cursor.execute(sql, params)
           ^^^^^^^^^^^^^^^^^^^^^^^^^^^^^^^^
django.db.utils.ProgrammingError: relation "django_session" does not exist
LINE 1: ...ession_data", "django_session"."expire_date" FROM "django_se...
                                                             ^

  File "/nix/store/6dhxaza18jl6d29yczsqp0nf7lr07avj-python3.11-django-4.2.12/lib/python3.11/site-packages/django/core/handlers/exception.py", line 55, in inner
    response = get_response(request)
               ^^^^^^^^^^^^^^^^^^^^^
  File "/nix/store/6dhxaza18jl6d29yczsqp0nf7lr07avj-python3.11-django-4.2.12/lib/python3.11/site-packages/django/utils/deprecation.py", line 134, in __call__
    response = response or self.get_response(request)
                           ^^^^^^^^^^^^^^^^^^^^^^^^^^
  File "/nix/store/6dhxaza18jl6d29yczsqp0nf7lr07avj-python3.11-django-4.2.12/lib/python3.11/site-packages/django/core/handlers/exception.py", line 57, in inner
    response = response_for_exception(request, exc)
               ^^^^^^^^^^^^^^^^^^^^^^^^^^^^^^^^^^^^
  File "/nix/store/6dhxaza18jl6d29yczsqp0nf7lr07avj-python3.11-django-4.2.12/lib/python3.11/site-packages/django/core/handlers/exception.py", line 140, in response_for_exception
    response = handle_uncaught_exception(
               ^^^^^^^^^^^^^^^^^^^^^^^^^^
  File "/nix/store/6dhxaza18jl6d29yczsqp0nf7lr07avj-python3.11-django-4.2.12/lib/python3.11/site-packages/django/core/handlers/exception.py", line 185, in handle_uncaught_exception
    return callback(request)
           ^^^^^^^^^^^^^^^^^
  File "/nix/store/6dhxaza18jl6d29yczsqp0nf7lr07avj-python3.11-django-4.2.12/lib/python3.11/site-packages/django/utils/decorators.py", line 126, in _wrapper_view
    result = middleware.process_request(request)
             ^^^^^^^^^^^^^^^^^^^^^^^^^^^^^^^^^^^
  File "/nix/store/6dhxaza18jl6d29yczsqp0nf7lr07avj-python3.11-django-4.2.12/lib/python3.11/site-packages/django/middleware/csrf.py", line 408, in process_request
    csrf_secret = self._get_secret(request)
                  ^^^^^^^^^^^^^^^^^^^^^^^^^
  File "/nix/store/6dhxaza18jl6d29yczsqp0nf7lr07avj-python3.11-django-4.2.12/lib/python3.11/site-packages/django/middleware/csrf.py", line 236, in _get_secret
    csrf_secret = request.session.get(CSRF_SESSION_KEY)
                  ^^^^^^^^^^^^^^^^^^^^^^^^^^^^^^^^^^^^^
  File "/nix/store/6dhxaza18jl6d29yczsqp0nf7lr07avj-python3.11-django-4.2.12/lib/python3.11/site-packages/django/contrib/sessions/backends/base.py", line 68, in get
    return self._session.get(key, default)
           ^^^^^^^^^^^^^
  File "/nix/store/6dhxaza18jl6d29yczsqp0nf7lr07avj-python3.11-django-4.2.12/lib/python3.11/site-packages/django/contrib/sessions/backends/base.py", line 192, in _get_session
    self._session_cache = self.load()
                          ^^^^^^^^^^^
  File "/nix/store/6dhxaza18jl6d29yczsqp0nf7lr07avj-python3.11-django-4.2.12/lib/python3.11/site-packages/django/contrib/sessions/backends/db.py", line 42, in load
    s = self._get_session_from_db()
        ^^^^^^^^^^^^^^^^^^^^^^^^^^^
[11/Feb/2025 13:47:21] "GET /?initialPath=%2F&id=%3Ar2bc%3A HTTP/1.1" 500 59
  File "/nix/store/6dhxaza18jl6d29yczsqp0nf7lr07avj-python3.11-django-4.2.12/lib/python3.11/site-packages/django/contrib/sessions/backends/db.py", line 32, in _get_session_from_db
    return self.model.objects.get(
           ^^^^^^^^^^^^^^^^^^^^^^^
  File "/nix/store/6dhxaza18jl6d29yczsqp0nf7lr07avj-python3.11-django-4.2.12/lib/python3.11/site-packages/django/db/models/manager.py", line 87, in manager_method
    return getattr(self.get_queryset(), name)(*args, **kwargs)
           ^^^^^^^^^^^^^^^^^^^^^^^^^^^^^^^^^^^^^^^^^^^^^^^^^^^
  File "/nix/store/6dhxaza18jl6d29yczsqp0nf7lr07avj-python3.11-django-4.2.12/lib/python3.11/site-packages/django/db/models/query.py", line 633, in get
    num = len(clone)
          ^^^^^^^^^^
  File "/nix/store/6dhxaza18jl6d29yczsqp0nf7lr07avj-python3.11-django-4.2.12/lib/python3.11/site-packages/django/db/models/query.py", line 380, in __len__
    self._fetch_all()
  File "/nix/store/6dhxaza18jl6d29yczsqp0nf7lr07avj-python3.11-django-4.2.12/lib/python3.11/site-packages/django/db/models/query.py", line 1881, in _fetch_all
    self._result_cache = list(self._iterable_class(self))
                         ^^^^^^^^^^^^^^^^^^^^^^^^^^^^^^^^
  File "/nix/store/6dhxaza18jl6d29yczsqp0nf7lr07avj-python3.11-django-4.2.12/lib/python3.11/site-packages/django/db/models/query.py", line 91, in __iter__
    results = compiler.execute_sql(
              ^^^^^^^^^^^^^^^^^^^^^
  File "/nix/store/6dhxaza18jl6d29yczsqp0nf7lr07avj-python3.11-django-4.2.12/lib/python3.11/site-packages/django/db/models/sql/compiler.py", line 1562, in execute_sql
    cursor.execute(sql, params)
  File "/nix/store/6dhxaza18jl6d29yczsqp0nf7lr07avj-python3.11-django-4.2.12/lib/python3.11/site-packages/django/db/backends/utils.py", line 67, in execute
    return self._execute_with_wrappers(
           ^^^^^^^^^^^^^^^^^^^^^^^^^^^^
  File "/nix/store/6dhxaza18jl6d29yczsqp0nf7lr07avj-python3.11-django-4.2.12/lib/python3.11/site-packages/django/db/backends/utils.py", line 80, in _execute_with_wrappers
    return executor(sql, params, many, context)
           ^^^^^^^^^^^^^^^^^^^^^^^^^^^^^^^^^^^^
  File "/nix/store/6dhxaza18jl6d29yczsqp0nf7lr07avj-python3.11-django-4.2.12/lib/python3.11/site-packages/django/db/backends/utils.py", line 84, in _execute
    with self.db.wrap_database_errors:
  File "/nix/store/6dhxaza18jl6d29yczsqp0nf7lr07avj-python3.11-django-4.2.12/lib/python3.11/site-packages/django/db/utils.py", line 91, in __exit__
    raise dj_exc_value.with_traceback(traceback) from exc_value
  File "/nix/store/6dhxaza18jl6d29yczsqp0nf7lr07avj-python3.11-django-4.2.12/lib/python3.11/site-packages/django/db/backends/utils.py", line 89, in _execute
    return self.cursor.execute(sql, params)
           ^^^^^^^^^^^^^^^^^^^^^^^^^^^^^^^^
django.db.utils.ProgrammingError: relation "django_session" does not exist
LINE 1: ...ession_data", "django_session"."expire_date" FROM "django_se...
                                                             ^


During handling of the above exception, another exception occurred:

Traceback (most recent call last):
  File "/nix/store/6dhxaza18jl6d29yczsqp0nf7lr07avj-python3.11-django-4.2.12/lib/python3.11/site-packages/django/contrib/sessions/backends/base.py", line 187, in _get_session
    return self._session_cache
           ^^^^^^^^^^^^^^^^^^^
AttributeError: 'SessionStore' object has no attribute '_session_cache'

During handling of the above exception, another exception occurred:

Traceback (most recent call last):
  File "/nix/store/6dhxaza18jl6d29yczsqp0nf7lr07avj-python3.11-django-4.2.12/lib/python3.11/site-packages/django/db/backends/utils.py", line 89, in _execute
    return self.cursor.execute(sql, params)
           ^^^^^^^^^^^^^^^^^^^^^^^^^^^^^^^^
psycopg2.errors.UndefinedTable: relation "django_session" does not exist
LINE 1: ...ession_data", "django_session"."expire_date" FROM "django_se...
                                                             ^


The above exception was the direct cause of the following exception:

Traceback (most recent call last):
  File "/nix/store/clx0mcir7qw8zk36zbr4jra789g3knf6-python3-3.11.10/lib/python3.11/wsgiref/handlers.py", line 137, in run
    self.result = application(self.environ, self.start_response)
                  ^^^^^^^^^^^^^^^^^^^^^^^^^^^^^^^^^^^^^^^^^^^^^^
  File "/nix/store/6dhxaza18jl6d29yczsqp0nf7lr07avj-python3.11-django-4.2.12/lib/python3.11/site-packages/django/core/handlers/wsgi.py", line 124, in __call__
    response = self.get_response(request)
               ^^^^^^^^^^^^^^^^^^^^^^^^^^
  File "/nix/store/6dhxaza18jl6d29yczsqp0nf7lr07avj-python3.11-django-4.2.12/lib/python3.11/site-packages/django/core/handlers/base.py", line 140, in get_response
    response = self._middleware_chain(request)
               ^^^^^^^^^^^^^^^^^^^^^^^^^^^^^^^
  File "/nix/store/6dhxaza18jl6d29yczsqp0nf7lr07avj-python3.11-django-4.2.12/lib/python3.11/site-packages/django/core/handlers/exception.py", line 57, in inner
    response = response_for_exception(request, exc)
               ^^^^^^^^^^^^^^^^^^^^^^^^^^^^^^^^^^^^
  File "/nix/store/6dhxaza18jl6d29yczsqp0nf7lr07avj-python3.11-django-4.2.12/lib/python3.11/site-packages/django/core/handlers/exception.py", line 140, in response_for_exception
    response = handle_uncaught_exception(
               ^^^^^^^^^^^^^^^^^^^^^^^^^^
  File "/nix/store/6dhxaza18jl6d29yczsqp0nf7lr07avj-python3.11-django-4.2.12/lib/python3.11/site-packages/django/core/handlers/exception.py", line 185, in handle_uncaught_exception
    return callback(request)
           ^^^^^^^^^^^^^^^^^
  File "/nix/store/6dhxaza18jl6d29yczsqp0nf7lr07avj-python3.11-django-4.2.12/lib/python3.11/site-packages/django/utils/decorators.py", line 126, in _wrapper_view
    result = middleware.process_request(request)
             ^^^^^^^^^^^^^^^^^^^^^^^^^^^^^^^^^^^
  File "/nix/store/6dhxaza18jl6d29yczsqp0nf7lr07avj-python3.11-django-4.2.12/lib/python3.11/site-packages/django/middleware/csrf.py", line 408, in process_request
    csrf_secret = self._get_secret(request)
                  ^^^^^^^^^^^^^^^^^^^^^^^^^
  File "/nix/store/6dhxaza18jl6d29yczsqp0nf7lr07avj-python3.11-django-4.2.12/lib/python3.11/site-packages/django/middleware/csrf.py", line 236, in _get_secret
    csrf_secret = request.session.get(CSRF_SESSION_KEY)
                  ^^^^^^^^^^^^^^^^^^^^^^^^^^^^^^^^^^^^^
  File "/nix/store/6dhxaza18jl6d29yczsqp0nf7lr07avj-python3.11-django-4.2.12/lib/python3.11/site-packages/django/contrib/sessions/backends/base.py", line 68, in get
    return self._session.get(key, default)
           ^^^^^^^^^^^^^
  File "/nix/store/6dhxaza18jl6d29yczsqp0nf7lr07avj-python3.11-django-4.2.12/lib/python3.11/site-packages/django/contrib/sessions/backends/base.py", line 192, in _get_session
    self._session_cache = self.load()
                          ^^^^^^^^^^^
  File "/nix/store/6dhxaza18jl6d29yczsqp0nf7lr07avj-python3.11-django-4.2.12/lib/python3.11/site-packages/django/contrib/sessions/backends/db.py", line 42, in load
    s = self._get_session_from_db()
        ^^^^^^^^^^^^^^^^^^^^^^^^^^^
  File "/nix/store/6dhxaza18jl6d29yczsqp0nf7lr07avj-python3.11-django-4.2.12/lib/python3.11/site-packages/django/contrib/sessions/backends/db.py", line 32, in _get_session_from_db
    return self.model.objects.get(
           ^^^^^^^^^^^^^^^^^^^^^^^
  File "/nix/store/6dhxaza18jl6d29yczsqp0nf7lr07avj-python3.11-django-4.2.12/lib/python3.11/site-packages/django/db/models/manager.py", line 87, in manager_method
    return getattr(self.get_queryset(), name)(*args, **kwargs)
           ^^^^^^^^^^^^^^^^^^^^^^^^^^^^^^^^^^^^^^^^^^^^^^^^^^^
  File "/nix/store/6dhxaza18jl6d29yczsqp0nf7lr07avj-python3.11-django-4.2.12/lib/python3.11/site-packages/django/db/models/query.py", line 633, in get
    num = len(clone)
          ^^^^^^^^^^
  File "/nix/store/6dhxaza18jl6d29yczsqp0nf7lr07avj-python3.11-django-4.2.12/lib/python3.11/site-packages/django/db/models/query.py", line 380, in __len__
    self._fetch_all()
  File "/nix/store/6dhxaza18jl6d29yczsqp0nf7lr07avj-python3.11-django-4.2.12/lib/python3.11/site-packages/django/db/models/query.py", line 1881, in _fetch_all
    self._result_cache = list(self._iterable_class(self))
                         ^^^^^^^^^^^^^^^^^^^^^^^^^^^^^^^^
  File "/nix/store/6dhxaza18jl6d29yczsqp0nf7lr07avj-python3.11-django-4.2.12/lib/python3.11/site-packages/django/db/models/query.py", line 91, in __iter__
    results = compiler.execute_sql(
              ^^^^^^^^^^^^^^^^^^^^^
  File "/nix/store/6dhxaza18jl6d29yczsqp0nf7lr07avj-python3.11-django-4.2.12/lib/python3.11/site-packages/django/db/models/sql/compiler.py", line 1562, in execute_sql
    cursor.execute(sql, params)
  File "/nix/store/6dhxaza18jl6d29yczsqp0nf7lr07avj-python3.11-django-4.2.12/lib/python3.11/site-packages/django/db/backends/utils.py", line 67, in execute
    return self._execute_with_wrappers(
           ^^^^^^^^^^^^^^^^^^^^^^^^^^^^
  File "/nix/store/6dhxaza18jl6d29yczsqp0nf7lr07avj-python3.11-django-4.2.12/lib/python3.11/site-packages/django/db/backends/utils.py", line 80, in _execute_with_wrappers
    return executor(sql, params, many, context)
           ^^^^^^^^^^^^^^^^^^^^^^^^^^^^^^^^^^^^
  File "/nix/store/6dhxaza18jl6d29yczsqp0nf7lr07avj-python3.11-django-4.2.12/lib/python3.11/site-packages/django/db/backends/utils.py", line 84, in _execute
    with self.db.wrap_database_errors:
  File "/nix/store/6dhxaza18jl6d29yczsqp0nf7lr07avj-python3.11-django-4.2.12/lib/python3.11/site-packages/django/db/utils.py", line 91, in __exit__
    raise dj_exc_value.with_traceback(traceback) from exc_value
  File "/nix/store/6dhxaza18jl6d29yczsqp0nf7lr07avj-python3.11-django-4.2.12/lib/python3.11/site-packages/django/db/backends/utils.py", line 89, in _execute
    return self.cursor.execute(sql, params)
           ^^^^^^^^^^^^^^^^^^^^^^^^^^^^^^^^
django.db.utils.ProgrammingError: relation "django_session" does not exist
LINE 1: ...ession_data", "django_session"."expire_date" FROM "django_se...
                                                             ^

[11/Feb/2025 13:47:21] "GET /?initialPath=%2F&id=%3Ar2bb%3A HTTP/1.1" 500 59