Error connecting to PostgreSQL: connection to server on socket "/run/postgresql/.s.PGSQL.5432" failed: No such file or directory
    Is the server running locally and accepting connections on that socket?

Performing system checks...

System check identified no issues (0 silenced).
Traceback (most recent call last):
  File "/nix/store/6dhxaza18jl6d29yczsqp0nf7lr07avj-python3.11-django-4.2.12/lib/python3.11/site-packages/django/db/backends/base/base.py", line 289, in ensure_connection
    self.connect()
  File "/nix/store/6dhxaza18jl6d29yczsqp0nf7lr07avj-python3.11-django-4.2.12/lib/python3.11/site-packages/django/utils/asyncio.py", line 26, in inner
    return func(*args, **kwargs)
           ^^^^^^^^^^^^^^^^^^^^^
  File "/nix/store/6dhxaza18jl6d29yczsqp0nf7lr07avj-python3.11-django-4.2.12/lib/python3.11/site-packages/django/db/backends/base/base.py", line 270, in connect
    self.connection = self.get_new_connection(conn_params)
                      ^^^^^^^^^^^^^^^^^^^^^^^^^^^^^^^^^^^^
  File "/nix/store/6dhxaza18jl6d29yczsqp0nf7lr07avj-python3.11-django-4.2.12/lib/python3.11/site-packages/django/utils/asyncio.py", line 26, in inner
    return func(*args, **kwargs)
           ^^^^^^^^^^^^^^^^^^^^^
  File "/nix/store/6dhxaza18jl6d29yczsqp0nf7lr07avj-python3.11-django-4.2.12/lib/python3.11/site-packages/django/db/backends/postgresql/base.py", line 275, in get_new_connection
    connection = self.Database.connect(**conn_params)
                 ^^^^^^^^^^^^^^^^^^^^^^^^^^^^^^^^^^^^
  File "/nix/store/ddadgv5z9rpdin70dcpdk2yflyv7hvxl-python3.11-psycopg2-2.9.9/lib/python3.11/site-packages/psycopg2/__init__.py", line 122, in connect
    conn = _connect(dsn, connection_factory=connection_factory, **kwasync)
           ^^^^^^^^^^^^^^^^^^^^^^^^^^^^^^^^^^^^^^^^^^^^^^^^^^^^^^^^^^^^^^^
psycopg2.OperationalError: connection to server at "ep-jolly-waterfall-a1owq4gt.ap-southeast-1.aws.neon.tech" (13.228.46.236), port 5432 failed: ERROR:  password authentication failed for user 'neondb_owner'


The above exception was the direct cause of the following exception:

Traceback (most recent call last):
  File "/home/runner/workspace/main.py", line 9, in <module>
    execute_from_command_line(["", "runserver", f"0.0.0.0:{port}", "--noreload"])
  File "/nix/store/6dhxaza18jl6d29yczsqp0nf7lr07avj-python3.11-django-4.2.12/lib/python3.11/site-packages/django/core/management/__init__.py", line 442, in execute_from_command_line
    utility.execute()
  File "/nix/store/6dhxaza18jl6d29yczsqp0nf7lr07avj-python3.11-django-4.2.12/lib/python3.11/site-packages/django/core/management/__init__.py", line 436, in execute
    self.fetch_command(subcommand).run_from_argv(self.argv)
  File "/nix/store/6dhxaza18jl6d29yczsqp0nf7lr07avj-python3.11-django-4.2.12/lib/python3.11/site-packages/django/core/management/base.py", line 412, in run_from_argv
    self.execute(*args, **cmd_options)
  File "/nix/store/6dhxaza18jl6d29yczsqp0nf7lr07avj-python3.11-django-4.2.12/lib/python3.11/site-packages/django/core/management/commands/runserver.py", line 74, in execute
    super().execute(*args, **options)
  File "/nix/store/6dhxaza18jl6d29yczsqp0nf7lr07avj-python3.11-django-4.2.12/lib/python3.11/site-packages/django/core/management/base.py", line 458, in execute
    output = self.handle(*args, **options)
             ^^^^^^^^^^^^^^^^^^^^^^^^^^^^^
  File "/nix/store/6dhxaza18jl6d29yczsqp0nf7lr07avj-python3.11-django-4.2.12/lib/python3.11/site-packages/django/core/management/commands/runserver.py", line 111, in handle
    self.run(**options)
  File "/nix/store/6dhxaza18jl6d29yczsqp0nf7lr07avj-python3.11-django-4.2.12/lib/python3.11/site-packages/django/core/management/commands/runserver.py", line 120, in run
    self.inner_run(None, **options)
  File "/nix/store/6dhxaza18jl6d29yczsqp0nf7lr07avj-python3.11-django-4.2.12/lib/python3.11/site-packages/django/core/management/commands/runserver.py", line 136, in inner_run
    self.check_migrations()
  File "/nix/store/6dhxaza18jl6d29yczsqp0nf7lr07avj-python3.11-django-4.2.12/lib/python3.11/site-packages/django/core/management/base.py", line 574, in check_migrations
    executor = MigrationExecutor(connections[DEFAULT_DB_ALIAS])
               ^^^^^^^^^^^^^^^^^^^^^^^^^^^^^^^^^^^^^^^^^^^^^^^^
  File "/nix/store/6dhxaza18jl6d29yczsqp0nf7lr07avj-python3.11-django-4.2.12/lib/python3.11/site-packages/django/db/migrations/executor.py", line 18, in __init__
    self.loader = MigrationLoader(self.connection)
                  ^^^^^^^^^^^^^^^^^^^^^^^^^^^^^^^^
  File "/nix/store/6dhxaza18jl6d29yczsqp0nf7lr07avj-python3.11-django-4.2.12/lib/python3.11/site-packages/django/db/migrations/loader.py", line 58, in __init__
    self.build_graph()
  File "/nix/store/6dhxaza18jl6d29yczsqp0nf7lr07avj-python3.11-django-4.2.12/lib/python3.11/site-packages/django/db/migrations/loader.py", line 235, in build_graph
    self.applied_migrations = recorder.applied_migrations()
                              ^^^^^^^^^^^^^^^^^^^^^^^^^^^^^
  File "/nix/store/6dhxaza18jl6d29yczsqp0nf7lr07avj-python3.11-django-4.2.12/lib/python3.11/site-packages/django/db/migrations/recorder.py", line 81, in applied_migrations
    if self.has_table():
       ^^^^^^^^^^^^^^^^
  File "/nix/store/6dhxaza18jl6d29yczsqp0nf7lr07avj-python3.11-django-4.2.12/lib/python3.11/site-packages/django/db/migrations/recorder.py", line 57, in has_table
    with self.connection.cursor() as cursor:
         ^^^^^^^^^^^^^^^^^^^^^^^^
  File "/nix/store/6dhxaza18jl6d29yczsqp0nf7lr07avj-python3.11-django-4.2.12/lib/python3.11/site-packages/django/utils/asyncio.py", line 26, in inner
    return func(*args, **kwargs)
           ^^^^^^^^^^^^^^^^^^^^^
  File "/nix/store/6dhxaza18jl6d29yczsqp0nf7lr07avj-python3.11-django-4.2.12/lib/python3.11/site-packages/django/db/backends/base/base.py", line 330, in cursor
    return self._cursor()
           ^^^^^^^^^^^^^^
  File "/nix/store/6dhxaza18jl6d29yczsqp0nf7lr07avj-python3.11-django-4.2.12/lib/python3.11/site-packages/django/db/backends/base/base.py", line 306, in _cursor
    self.ensure_connection()
  File "/nix/store/6dhxaza18jl6d29yczsqp0nf7lr07avj-python3.11-django-4.2.12/lib/python3.11/site-packages/django/utils/asyncio.py", line 26, in inner
    return func(*args, **kwargs)
           ^^^^^^^^^^^^^^^^^^^^^
  File "/nix/store/6dhxaza18jl6d29yczsqp0nf7lr07avj-python3.11-django-4.2.12/lib/python3.11/site-packages/django/db/backends/base/base.py", line 288, in ensure_connection
    with self.wrap_database_errors:
  File "/nix/store/6dhxaza18jl6d29yczsqp0nf7lr07avj-python3.11-django-4.2.12/lib/python3.11/site-packages/django/db/utils.py", line 91, in __exit__
    raise dj_exc_value.with_traceback(traceback) from exc_value
  File "/nix/store/6dhxaza18jl6d29yczsqp0nf7lr07avj-python3.11-django-4.2.12/lib/python3.11/site-packages/django/db/backends/base/base.py", line 289, in ensure_connection
    self.connect()
  File "/nix/store/6dhxaza18jl6d29yczsqp0nf7lr07avj-python3.11-django-4.2.12/lib/python3.11/site-packages/django/utils/asyncio.py", line 26, in inner
    return func(*args, **kwargs)
           ^^^^^^^^^^^^^^^^^^^^^
  File "/nix/store/6dhxaza18jl6d29yczsqp0nf7lr07avj-python3.11-django-4.2.12/lib/python3.11/site-packages/django/db/backends/base/base.py", line 270, in connect
    self.connection = self.get_new_connection(conn_params)
                      ^^^^^^^^^^^^^^^^^^^^^^^^^^^^^^^^^^^^
  File "/nix/store/6dhxaza18jl6d29yczsqp0nf7lr07avj-python3.11-django-4.2.12/lib/python3.11/site-packages/django/utils/asyncio.py", line 26, in inner
    return func(*args, **kwargs)
           ^^^^^^^^^^^^^^^^^^^^^
  File "/nix/store/6dhxaza18jl6d29yczsqp0nf7lr07avj-python3.11-django-4.2.12/lib/python3.11/site-packages/django/db/backends/postgresql/base.py", line 275, in get_new_connection
    connection = self.Database.connect(**conn_params)
                 ^^^^^^^^^^^^^^^^^^^^^^^^^^^^^^^^^^^^
  File "/nix/store/ddadgv5z9rpdin70dcpdk2yflyv7hvxl-python3.11-psycopg2-2.9.9/lib/python3.11/site-packages/psycopg2/__init__.py", line 122, in connect
    conn = _connect(dsn, connection_factory=connection_factory, **kwasync)
           ^^^^^^^^^^^^^^^^^^^^^^^^^^^^^^^^^^^^^^^^^^^^^^^^^^^^^^^^^^^^^^^
django.db.utils.OperationalError: connection to server at "ep-jolly-waterfall-a1owq4gt.ap-southeast-1.aws.neon.tech" (13.228.46.236), port 5432 failed: ERROR:  password authentication failed for user 'neondb_owner'