Connected to PostgreSQL database. Version: PostgreSQL 16.6 on x86_64-pc-linux-gnu, compiled by gcc (Debian 10.2.1-6) 10.2.1 20210110, 64-bit
Database connection closed.
Connected to PostgreSQL database. Version: PostgreSQL 16.6 on x86_64-pc-linux-gnu, compiled by gcc (Debian 10.2.1-6) 10.2.1 20210110, 64-bit
Database connection closed.
Watching for file changes with StatReloader
Exception in thread django-main-thread:
Traceback (most recent call last):
  File "/nix/store/clx0mcir7qw8zk36zbr4jra789g3knf6-python3-3.11.10/lib/python3.11/threading.py", line 1045, in _bootstrap_inner
    self.run()
  File "/nix/store/clx0mcir7qw8zk36zbr4jra789g3knf6-python3-3.11.10/lib/python3.11/threading.py", line 982, in run
    self._target(*self._args, **self._kwargs)
  File "/nix/store/6dhxaza18jl6d29yczsqp0nf7lr07avj-python3.11-django-4.2.12/lib/python3.11/site-packages/django/utils/autoreload.py", line 64, in wrapper
    fn(*args, **kwargs)
  File "/nix/store/6dhxaza18jl6d29yczsqp0nf7lr07avj-python3.11-django-4.2.12/lib/python3.11/site-packages/django/core/management/commands/runserver.py", line 125, in inner_run
    autoreload.raise_last_exception()
  File "/nix/store/6dhxaza18jl6d29yczsqp0nf7lr07avj-python3.11-django-4.2.12/lib/python3.11/site-packages/django/utils/autoreload.py", line 87, in raise_last_exception
    raise _exception[1]
  File "/nix/store/6dhxaza18jl6d29yczsqp0nf7lr07avj-python3.11-django-4.2.12/lib/python3.11/site-packages/django/core/management/__init__.py", line 394, in execute
    autoreload.check_errors(django.setup)()
  File "/nix/store/6dhxaza18jl6d29yczsqp0nf7lr07avj-python3.11-django-4.2.12/lib/python3.11/site-packages/django/utils/autoreload.py", line 64, in wrapper
    fn(*args, **kwargs)
  File "/nix/store/6dhxaza18jl6d29yczsqp0nf7lr07avj-python3.11-django-4.2.12/lib/python3.11/site-packages/django/__init__.py", line 24, in setup
    apps.populate(settings.INSTALLED_APPS)
  File "/nix/store/6dhxaza18jl6d29yczsqp0nf7lr07avj-python3.11-django-4.2.12/lib/python3.11/site-packages/django/apps/registry.py", line 91, in populate
    app_config = AppConfig.create(entry)
                 ^^^^^^^^^^^^^^^^^^^^^^^
  File "/nix/store/6dhxaza18jl6d29yczsqp0nf7lr07avj-python3.11-django-4.2.12/lib/python3.11/site-packages/django/apps/config.py", line 193, in create
    import_module(entry)
  File "/nix/store/clx0mcir7qw8zk36zbr4jra789g3knf6-python3-3.11.10/lib/python3.11/importlib/__init__.py", line 126, in import_module
    return _bootstrap._gcd_import(name[level:], package, level)
           ^^^^^^^^^^^^^^^^^^^^^^^^^^^^^^^^^^^^^^^^^^^^^^^^^^^^
  File "<frozen importlib._bootstrap>", line 1204, in _gcd_import
  File "<frozen importlib._bootstrap>", line 1176, in _find_and_load
  File "<frozen importlib._bootstrap>", line 1140, in _find_and_load_unlocked
ModuleNotFoundError: No module named 'captcha'
